Workbook
Name val_fEst: MOTOR_DASHBOARD!$W$4:$W$8
Name val_Rol: PARAMETROS!$C$5:$C$6
Name val_EstadoPersona: PARAMETROS!$B$5:$B$6
Name val_fSup: MOTOR_DASHBOARD!$V$4:$V$20
Name val_Supervisor: PARAMETROS!$G$5:$G$20
Name val_fReg: MOTOR_DASHBOARD!$U$4:$U$10
Name val_TipoMov: PARAMETROS!$E$5:$E$13
Name val_fMes: MOTOR_DASHBOARD!$X$4:$X$16
Name val_Generacion: PARAMETROS!$F$5:$F$6
Name val_Regional: PARAMETROS!$A$5:$A$10
Name val_EstadoCred: PARAMETROS!$D$5:$D$8

Sheet INICIO
B1: SISTEMA BEX - CONTROL DE CREDENCIALES
B2: ? COMO USAR ESTE ARCHIVO
B3: Sistema integrado y automatico. Ingrese datos solo en MOVIMIENTOS, PERSONAL e INVENTARIO_GENERAL. El DASHBOARD, el BUSCADOR y los indicadores se calculan solos. Use los botones para navegar.
B5: NAVEGACION
B6: Ir a DASHBOARD | C6: Indicadores, graficos y filtros
B7: Ir a BUSCADOR | C7: Buscar credencial por codigo, nombre o telefono
B8: Ir a INVENTARIO_GENERAL | C8: Fuente central: todas las credenciales
B9: Ir a PERSONAL | C9: Tabla maestra de personas
B10: Ir a MOVIMIENTOS | C10: Historial de eventos (entradas/salidas)
B11: Ir a PARAMETROS | C11: Listas maestras del sistema
B13: RESUMEN RAPIDO
B14: Total credenciales | C14: =COUNTA(INVENTARIO_GENERAL!$A$5:$A$181) -> 177
B15: Asignadas | C15: =COUNTIF(INVENTARIO_GENERAL!$C$5:$C$181,"ASIGNADO") -> 73
B16: Disponibles | C16: =COUNTIF(INVENTARIO_GENERAL!$C$5:$C$181,"DISPONIBLE") -> 68
B17: Perdidas | C17: =COUNTIF(INVENTARIO_GENERAL!$C$5:$C$181,"PERDIDO") -> 1
B18: Total personal | C18: =COUNTA(PERSONAL!$A$5:$A$135) -> 131

Sheet DASHBOARD
A1: DASHBOARD EJECUTIVO - Control de Credenciales BEX
A2: ? COMO USAR ESTA HOJA
A3: Todos los indicadores se calculan solos desde INVENTARIO_GENERAL y MOVIMIENTOS. Al final de la hoja hay un PANEL DE FILTROS (menus desplegables) que actua como segmentadores. Los graficos se actualizan automaticamente.
A5: INDICADORES CLAVE
A6: TOTAL CREDENCIALES | D6: ASIGNADAS | G6: DISPONIBLES | J6: POR ASIGNAR | M6: PERDIDAS
A7: =COUNTA(INVENTARIO_GENERAL!$A$5:$A$181) -> 177 | D7: =COUNTIF(INVENTARIO_GENERAL!$C$5:$C$181,"ASIGNADO") -> 73 | G7: =COUNTIF(INVENTARIO_GENERAL!$C$5:$C$181,"DISPONIBLE") -> 68 | J7: =COUNTIF(INVENTARIO_GENERAL!$C$5:$C$181,"POR ASIGNAR") -> 35 | M7: =COUNTIF(INVENTARIO_GENERAL!$C$5:$C$181,"PERDIDO") -> 1
A9: DEVUELTAS | D9: STOCK EN OFICINA | G9: STOCK EN USO | J9: PERSONAL ACTIVO | M9: SUPERVISORES
A10: =COUNTIF(MOVIMIENTOS!$C$5:$C$53,"DEVOLUCION") -> 0 | D10: =COUNTIF(INVENTARIO_GENERAL!$C$5:$C$181,"DISPONIBLE") -> 68 | G10: =COUNTIF(INVENTARIO_GENERAL!$C$5:$C$181,"ASIGNADO") -> 73 | J10: =COUNTIF(PERSONAL!$F$5:$F$135,"ACTIVO") -> 94 | M10: =COUNTIF(PERSONAL!$C$5:$C$135,"SUPERVISOR") -> 16
A13: CREDENCIALES POR REGIONAL | H13: DISTRIBUCION POR ESTADO
A14: Regional | B14: Cantidad | H14: Estado | I14: Cantidad
A15: =MOTOR_DASHBOARD!D4 -> COCHABAMBA | B15: =MOTOR_DASHBOARD!E4 -> 30 | H15: =MOTOR_DASHBOARD!A4 -> ASIGNADO | I15: =MOTOR_DASHBOARD!B4 -> 73
A16: =MOTOR_DASHBOARD!D5 -> LA PAZ | B16: =MOTOR_DASHBOARD!E5 -> 39 | H16: =MOTOR_DASHBOARD!A5 -> DISPONIBLE | I16: =MOTOR_DASHBOARD!B5 -> 68
A17: =MOTOR_DASHBOARD!D6 -> ORURO | B17: =MOTOR_DASHBOARD!E6 -> 10 | H17: =MOTOR_DASHBOARD!A6 -> POR ASIGNAR | I17: =MOTOR_DASHBOARD!B6 -> 35
A18: =MOTOR_DASHBOARD!D7 -> SANTA CRUZ | B18: =MOTOR_DASHBOARD!E7 -> 85 | H18: =MOTOR_DASHBOARD!A7 -> PERDIDO | I18: =MOTOR_DASHBOARD!B7 -> 1
A19: =MOTOR_DASHBOARD!D8 -> SUCRE | B19: =MOTOR_DASHBOARD!E8 -> 6
A20: =MOTOR_DASHBOARD!D9 -> TARIJA | B20: =MOTOR_DASHBOARD!E9 -> 7
A23: ULTIMOS MOVIMIENTOS REGISTRADOS
A24: ID_Movimiento | B24: Fecha | C24: Tipo_Movimiento | D24: Codigo_Activo | E24: Nombre | F24: Supervisor | G24: Regional
A25: {=IFERROR(INDEX(MOVIMIENTOS!$A$5:$A$53,COUNTA(MOVIMIENTOS!$A$5:$A$53)-9),"")} -> MOV-0040 | B25: {=IFERROR(INDEX(MOVIMIENTOS!$B$5:$B$53,COUNTA(MOVIMIENTOS!$A$5:$A$53)-9),"")} -> 46176 | C25: {=IFERROR(INDEX(MOVIMIENTOS!$C$5:$C$53,COUNTA(MOVIMIENTOS!$A$5:$A$53)-9),"")} -> ENTREGA INICIAL | D25: {=IFERROR(INDEX(MOVIMIENTOS!$D$5:$D$53,COUNTA(MOVIMIENTOS!$A$5:$A$53)-9),"")} -> BEX-2039 | E25: {=IFERROR(INDEX(MOVIMIENTOS!$F$5:$F$53,COUNTA(MOVIMIENTOS!$A$5:$A$53)-9),"")} -> CESAR OSCAR LAURA CHUYMA | F25: {=IFERROR(INDEX(MOVIMIENTOS!$G$5:$G$53,COUNTA(MOVIMIENTOS!$A$5:$A$53)-9),"")} -> JOEL DAVID HUANCA HUANCA | G25: {=IFERROR(INDEX(MOVIMIENTOS!$H$5:$H$53,COUNTA(MOVIMIENTOS!$A$5:$A$53)-9),"")} -> LA PAZ
A26: {=IFERROR(INDEX(MOVIMIENTOS!$A$5:$A$53,COUNTA(MOVIMIENTOS!$A$5:$A$53)-8),"")} -> MOV-0041 | B26: {=IFERROR(INDEX(MOVIMIENTOS!$B$5:$B$53,COUNTA(MOVIMIENTOS!$A$5:$A$53)-8),"")} -> 46176 | C26: {=IFERROR(INDEX(MOVIMIENTOS!$C$5:$C$53,COUNTA(MOVIMIENTOS!$A$5:$A$53)-8),"")} -> ENTREGA INICIAL | D26: {=IFERROR(INDEX(MOVIMIENTOS!$D$5:$D$53,COUNTA(MOVIMIENTOS!$A$5:$A$53)-8),"")} -> BEX-2040 | E26: {=IFERROR(INDEX(MOVIMIENTOS!$F$5:$F$53,COUNTA(MOVIMIENTOS!$A$5:$A$53)-8),"")} -> MILENKO ADRIANA ORDONEZ NUNEZ | F26: {=IFERROR(INDEX(MOVIMIENTOS!$G$5:$G$53,COUNTA(MOVIMIENTOS!$A$5:$A$53)-8),"")} -> MILENKO ADRIANA ORDONEZ NUNEZ | G26: {=IFERROR(INDEX(MOVIMIENTOS!$H$5:$H$53,COUNTA(MOVIMIENTOS!$A$5:$A$53)-8),"")} -> LA PAZ
A27: {=IFERROR(INDEX(MOVIMIENTOS!$A$5:$A$53,COUNTA(MOVIMIENTOS!$A$5:$A$53)-7),"")} -> MOV-0042 | B27: {=IFERROR(INDEX(MOVIMIENTOS!$B$5:$B$53,COUNTA(MOVIMIENTOS!$A$5:$A$53)-7),"")} -> 46176 | C27: {=IFERROR(INDEX(MOVIMIENTOS!$C$5:$C$53,COUNTA(MOVIMIENTOS!$A$5:$A$53)-7),"")} -> ENTREGA INICIAL | D27: {=IFERROR(INDEX(MOVIMIENTOS!$D$5:$D$53,COUNTA(MOVIMIENTOS!$A$5:$A$53)-7),"")} -> BEX-2041 | E27: {=IFERROR(INDEX(MOVIMIENTOS!$F$5:$F$53,COUNTA(MOVIMIENTOS!$A$5:$A$53)-7),"")} -> RUTH CELINA PONCE PACO | F27: {=IFERROR(INDEX(MOVIMIENTOS!$G$5:$G$53,COUNTA(MOVIMIENTOS!$A$5:$A$53)-7),"")} -> MILENKO ADRIANA ORDONEZ NUNEZ | G27: {=IFERROR(INDEX(MOVIMIENTOS!$H$5:$H$53,COUNTA(MOVIMIENTOS!$A$5:$A$53)-7),"")} -> LA PAZ
A28: {=IFERROR(INDEX(MOVIMIENTOS!$A$5:$A$53,COUNTA(MOVIMIENTOS!$A$5:$A$53)-6),"")} -> MOV-0043 | B28: {=IFERROR(INDEX(MOVIMIENTOS!$B$5:$B$53,COUNTA(MOVIMIENTOS!$A$5:$A$53)-6),"")} -> 46176 | C28: {=IFERROR(INDEX(MOVIMIENTOS!$C$5:$C$53,COUNTA(MOVIMIENTOS!$A$5:$A$53)-6),"")} -> ENTREGA INICIAL | D28: {=IFERROR(INDEX(MOVIMIENTOS!$D$5:$D$53,COUNTA(MOVIMIENTOS!$A$5:$A$53)-6),"")} -> BEX-2042 | E28: {=IFERROR(INDEX(MOVIMIENTOS!$F$5:$F$53,COUNTA(MOVIMIENTOS!$A$5:$A$53)-6),"")} -> SILVANA ASUNCION ORDONEZ NUNEZ | F28: {=IFERROR(INDEX(MOVIMIENTOS!$G$5:$G$53,COUNTA(MOVIMIENTOS!$A$5:$A$53)-6),"")} -> MILENKO ADRIANA ORDONEZ NUNEZ | G28: {=IFERROR(INDEX(MOVIMIENTOS!$H$5:$H$53,COUNTA(MOVIMIENTOS!$A$5:$A$53)-6),"")} -> LA PAZ
A29: {=IFERROR(INDEX(MOVIMIENTOS!$A$5:$A$53,COUNTA(MOVIMIENTOS!$A$5:$A$53)-5),"")} -> MOV-0044 | B29: {=IFERROR(INDEX(MOVIMIENTOS!$B$5:$B$53,COUNTA(MOVIMIENTOS!$A$5:$A$53)-5),"")} -> 46176 | C29: {=IFERROR(INDEX(MOVIMIENTOS!$C$5:$C$53,COUNTA(MOVIMIENTOS!$A$5:$A$53)-5),"")} -> ENTREGA INICIAL | D29: {=IFERROR(INDEX(MOVIMIENTOS!$D$5:$D$53,COUNTA(MOVIMIENTOS!$A$5:$A$53)-5),"")} -> BEX-2043 | E29: {=IFERROR(INDEX(MOVIMIENTOS!$F$5:$F$53,COUNTA(MOVIMIENTOS!$A$5:$A$53)-5),"")} -> ADILSON ALMANZA GOMEZ | F29: {=IFERROR(INDEX(MOVIMIENTOS!$G$5:$G$53,COUNTA(MOVIMIENTOS!$A$5:$A$53)-5),"")} -> MIRIAM ROSA CHAMBI QUISPE | G29: {=IFERROR(INDEX(MOVIMIENTOS!$H$5:$H$53,COUNTA(MOVIMIENTOS!$A$5:$A$53)-5),"")} -> ORURO
A30: {=IFERROR(INDEX(MOVIMIENTOS!$A$5:$A$53,COUNTA(MOVIMIENTOS!$A$5:$A$53)-4),"")} -> MOV-0045 | B30: {=IFERROR(INDEX(MOVIMIENTOS!$B$5:$B$53,COUNTA(MOVIMIENTOS!$A$5:$A$53)-4),"")} -> 46176 | C30: {=IFERROR(INDEX(MOVIMIENTOS!$C$5:$C$53,COUNTA(MOVIMIENTOS!$A$5:$A$53)-4),"")} -> ENTREGA INICIAL | D30: {=IFERROR(INDEX(MOVIMIENTOS!$D$5:$D$53,COUNTA(MOVIMIENTOS!$A$5:$A$53)-4),"")} -> BEX-2044 | E30: {=IFERROR(INDEX(MOVIMIENTOS!$F$5:$F$53,COUNTA(MOVIMIENTOS!$A$5:$A$53)-4),"")} -> ARACELI MARLENE TAPIA GUERRA | F30: {=IFERROR(INDEX(MOVIMIENTOS!$G$5:$G$53,COUNTA(MOVIMIENTOS!$A$5:$A$53)-4),"")} -> MIRIAM ROSA CHAMBI QUISPE | G30: {=IFERROR(INDEX(MOVIMIENTOS!$H$5:$H$53,COUNTA(MOVIMIENTOS!$A$5:$A$53)-4),"")} -> ORURO
A31: {=IFERROR(INDEX(MOVIMIENTOS!$A$5:$A$53,COUNTA(MOVIMIENTOS!$A$5:$A$53)-3),"")} -> MOV-0046 | B31: {=IFERROR(INDEX(MOVIMIENTOS!$B$5:$B$53,COUNTA(MOVIMIENTOS!$A$5:$A$53)-3),"")} -> 46176 | C31: {=IFERROR(INDEX(MOVIMIENTOS!$C$5:$C$53,COUNTA(MOVIMIENTOS!$A$5:$A$53)-3),"")} -> REPOSICION | D31: {=IFERROR(INDEX(MOVIMIENTOS!$D$5:$D$53,COUNTA(MOVIMIENTOS!$A$5:$A$53)-3),"")} -> BEX-2045 | E31: {=IFERROR(INDEX(MOVIMIENTOS!$F$5:$F$53,COUNTA(MOVIMIENTOS!$A$5:$A$53)-3),"")} -> BRENDA XIMENA BARBA VACA | F31: {=IFERROR(INDEX(MOVIMIENTOS!$G$5:$G$53,COUNTA(MOVIMIENTOS!$A$5:$A$53)-3),"")} -> BEATRIZ OVIEDO OVIEDO | G31: {=IFERROR(INDEX(MOVIMIENTOS!$H$5:$H$53,COUNTA(MOVIMIENTOS!$A$5:$A$53)-3),"")} -> SANTA CRUZ
A32: {=IFERROR(INDEX(MOVIMIENTOS!$A$5:$A$53,COUNTA(MOVIMIENTOS!$A$5:$A$53)-2),"")} -> MOV-0047 | B32: {=IFERROR(INDEX(MOVIMIENTOS!$B$5:$B$53,COUNTA(MOVIMIENTOS!$A$5:$A$53)-2),"")} -> 46176 | C32: {=IFERROR(INDEX(MOVIMIENTOS!$C$5:$C$53,COUNTA(MOVIMIENTOS!$A$5:$A$53)-2),"")} -> REPOSICION | D32: {=IFERROR(INDEX(MOVIMIENTOS!$D$5:$D$53,COUNTA(MOVIMIENTOS!$A$5:$A$53)-2),"")} -> BEX-2046 | E32: {=IFERROR(INDEX(MOVIMIENTOS!$F$5:$F$53,COUNTA(MOVIMIENTOS!$A$5:$A$53)-2),"")} -> MARCO ANTONIO ESCOBAR ALVAREZ | F32: {=IFERROR(INDEX(MOVIMIENTOS!$G$5:$G$53,COUNTA(MOVIMIENTOS!$A$5:$A$53)-2),"")} -> BEATRIZ OVIEDO OVIEDO | G32: {=IFERROR(INDEX(MOVIMIENTOS!$H$5:$H$53,COUNTA(MOVIMIENTOS!$A$5:$A$53)-2),"")} -> SANTA CRUZ
A33: {=IFERROR(INDEX(MOVIMIENTOS!$A$5:$A$53,COUNTA(MOVIMIENTOS!$A$5:$A$53)-1),"")} -> MOV-0048 | B33: {=IFERROR(INDEX(MOVIMIENTOS!$B$5:$B$53,COUNTA(MOVIMIENTOS!$A$5:$A$53)-1),"")} -> 46176 | C33: {=IFERROR(INDEX(MOVIMIENTOS!$C$5:$C$53,COUNTA(MOVIMIENTOS!$A$5:$A$53)-1),"")} -> PERDIDA | D33: {=IFERROR(INDEX(MOVIMIENTOS!$D$5:$D$53,COUNTA(MOVIMIENTOS!$A$5:$A$53)-1),"")} -> BEX-0518 | E33: {=IFERROR(INDEX(MOVIMIENTOS!$F$5:$F$53,COUNTA(MOVIMIENTOS!$A$5:$A$53)-1),"")} -> MARCO ANTONIO ESCOBAR ALVAREZ | F33: {=IFERROR(INDEX(MOVIMIENTOS!$G$5:$G$53,COUNTA(MOVIMIENTOS!$A$5:$A$53)-1),"")} -> BEATRIZ OVIEDO OVIEDO | G33: {=IFERROR(INDEX(MOVIMIENTOS!$H$5:$H$53,COUNTA(MOVIMIENTOS!$A$5:$A$53)-1),"")} -> SANTA CRUZ
A34: {=IFERROR(INDEX(MOVIMIENTOS!$A$5:$A$53,COUNTA(MOVIMIENTOS!$A$5:$A$53)+0),"")} -> MOV-0049 | B34: {=IFERROR(INDEX(MOVIMIENTOS!$B$5:$B$53,COUNTA(MOVIMIENTOS!$A$5:$A$53)+0),"")} -> 46176 | C34: {=IFERROR(INDEX(MOVIMIENTOS!$C$5:$C$53,COUNTA(MOVIMIENTOS!$A$5:$A$53)+0),"")} -> PERDIDA | D34: {=IFERROR(INDEX(MOVIMIENTOS!$D$5:$D$53,COUNTA(MOVIMIENTOS!$A$5:$A$53)+0),"")} -> BEX-2045 | E34: {=IFERROR(INDEX(MOVIMIENTOS!$F$5:$F$53,COUNTA(MOVIMIENTOS!$A$5:$A$53)+0),"")} -> BRENDA XIMENA BARBA VACA | F34: {=IFERROR(INDEX(MOVIMIENTOS!$G$5:$G$53,COUNTA(MOVIMIENTOS!$A$5:$A$53)+0),"")} -> BEATRIZ OVIEDO OVIEDO | G34: {=IFERROR(INDEX(MOVIMIENTOS!$H$5:$H$53,COUNTA(MOVIMIENTOS!$A$5:$A$53)+0),"")} -> SANTA CRUZ
A102: PANEL DE FILTROS INTERACTIVOS (funcionan como segmentadores)
A103: Regional: | B103: (TODOS) | D103: Supervisor: | E103: (TODOS) | G103: Estado: | H103: (TODOS) | J103: En filtro: | K103: =SUMPRODUCT((IF($B$103="(TODOS)",1,--(INVENTARIO_GENERAL!$G103=$B$103)))*(IF($E$103="(TODOS)",1,--(INVENTARIO_GENERAL!$F103=$E$103)))*(IF($H$103="(TODOS)",1,--(INVENTARIO_GENERAL!$C103=$H$103)))) -> 1
A105: RESULTADO FILTRADO (primeras 30 filas; cambie los menus de arriba)
A106: Codigo_Activo | B106: Tipo_Credencial | C106: Estado_Actual | D106: Responsable_Actual | E106: Telefono | F106: Supervisor | G106: Regional | H106: Fecha_Ultima_Asignacion | I106: Fecha_Ultima_Devolucion | J106: Cantidad_Perdidas | K106: Dias_En_Uso | L106: Observaciones
A107: =IFERROR(TAKE(_xlws.FILTER(TablaInventarioGeneral,(IF($B$103="(TODOS)",1,--(INVENTARIO_GENERAL!$G107=$B$103)))*(IF($E$103="(TODOS)",1,--(INVENTARIO_GENERAL!$F107=$E$103)))*(IF($H$103="(TODOS)",1,--(INVENTARIO_GENERAL!$C107=$H$103)))),30),"Sin resultados para este filtro") -> Sin resultados para este filtro

Sheet BUSCADOR
A1: BUSCADOR INTELIGENTE - Sistema BEX
A2: ? COMO USAR ESTA HOJA
A3: Escriba un codigo BEX en C5 (ej: BEX-0152) o un nombre/telefono en C6. Los resultados y el historial se muestran automaticamente. Si esta en oficina vera DISPONIBLE EN OFICINA; si se perdio, PERDIDA.
B5: BUSCAR POR CODIGO BEX: | C5: BEX-0151
B6: BUSCAR POR NOMBRE / TELEFONO: | C6: JORGE SAAVEDRA
A8: RESULTADO - BUSQUEDA POR CODIGO BEX
B9: CODIGO BEX: | C9: {=IF($C$5="","-",IFERROR(XLOOKUP($C$5,INVENTARIO_GENERAL!$A$5:$A$181,INVENTARIO_GENERAL!$A$5:$A$181),"NO ENCONTRADO"))} -> BEX-0151
B10: TIPO DE CREDENCIAL: | C10: {=IF($C$5="","-",IFERROR(XLOOKUP($C$5,INVENTARIO_GENERAL!$A$5:$A$181,INVENTARIO_GENERAL!$B$5:$B$181),"-"))} -> LEGACY (BEX-0xxx)
B11: ESTADO ACTUAL:
B12: RESPONSABLE ACTUAL: | C12: {=IF($C$5="","-",IFERROR(XLOOKUP($C$5,INVENTARIO_GENERAL!$A$5:$A$181,INVENTARIO_GENERAL!$D$5:$D$181),"-"))} -> SAMIEL ARTURO TORRICOS VILLARREAL
B13: TELEFONO: | C13: {=IF($C$5="","-",IFERROR(XLOOKUP($C$5,INVENTARIO_GENERAL!$A$5:$A$181,INVENTARIO_GENERAL!$E$5:$E$181),"-"))} -> POR REGISTRAR
B14: SUPERVISOR: | C14: {=IF($C$5="","-",IFERROR(XLOOKUP($C$5,INVENTARIO_GENERAL!$A$5:$A$181,INVENTARIO_GENERAL!$F$5:$F$181),"-"))} -> CLAUDIA SHASKIA CALLE NINA
B15: REGIONAL: | C15: {=IF($C$5="","-",IFERROR(XLOOKUP($C$5,INVENTARIO_GENERAL!$A$5:$A$181,INVENTARIO_GENERAL!$G$5:$G$181),"-"))} -> LA PAZ
B16: FECHA ASIGNACION: | C16: {=IF($C$5="","-",IFERROR(XLOOKUP($C$5,INVENTARIO_GENERAL!$A$5:$A$181,INVENTARIO_GENERAL!$H$5:$H$181),"-"))}
B17: FECHA DEVOLUCION: | C17: {=IF($C$5="","-",IFERROR(XLOOKUP($C$5,INVENTARIO_GENERAL!$A$5:$A$181,INVENTARIO_GENERAL!$I$5:$I$181),"-"))}
B18: CANTIDAD PERDIDAS: | C18: {=IF($C$5="","-",IFERROR(XLOOKUP($C$5,INVENTARIO_GENERAL!$A$5:$A$181,INVENTARIO_GENERAL!$J$5:$J$181),"-"))} -> 0
B19: OBSERVACIONES: | C19: {=IF($C$5="","-",IFERROR(XLOOKUP($C$5,INVENTARIO_GENERAL!$A$5:$A$181,INVENTARIO_GENERAL!$L$5:$L$181),"-"))} -> Credencial antiguo
A21: RESULTADO - BUSQUEDA POR NOMBRE / TELEFONO
B22: NOMBRE COMPLETO: | C22: {=IF($C$6="","-",IFERROR(IFERROR(XLOOKUP($C$6,PERSONAL!$B$5:$B$135,PERSONAL!$B$5:$B$135),XLOOKUP($C$6,PERSONAL!$A$5:$A$135,PERSONAL!$B$5:$B$135)),"NO ENCONTRADO"))} -> JORGE SAAVEDRA
B23: TELEFONO: | C23: {=IF($C$6="","-",IFERROR(XLOOKUP($C$22,PERSONAL!$B$5:$B$135,PERSONAL!$A$5:$A$135),"-"))} -> POR REGISTRAR
B24: ROL: | C24: {=IF($C$6="","-",IFERROR(XLOOKUP($C$22,PERSONAL!$B$5:$B$135,PERSONAL!$C$5:$C$135),"-"))} -> SUPERVISOR
B25: SUPERVISOR: | C25: {=IF($C$6="","-",IFERROR(XLOOKUP($C$22,PERSONAL!$B$5:$B$135,PERSONAL!$D$5:$D$135),"-"))} -> JORGE SAAVEDRA
B26: REGIONAL: | C26: {=IF($C$6="","-",IFERROR(XLOOKUP($C$22,PERSONAL!$B$5:$B$135,PERSONAL!$E$5:$E$135),"-"))} -> SANTA CRUZ
B27: ESTADO: | C27: {=IF($C$6="","-",IFERROR(XLOOKUP($C$22,PERSONAL!$B$5:$B$135,PERSONAL!$F$5:$F$135),"-"))} -> ACTIVO
B28: CREDENCIAL ACTUAL: | C28: {=IF($C$6="","-",IFERROR(XLOOKUP($C$22,PERSONAL!$B$5:$B$135,PERSONAL!$G$5:$G$135),"-"))} -> BEX-2000
B29: OBSERVACIONES: | C29: {=IF($C$6="","-",IFERROR(XLOOKUP($C$22,PERSONAL!$B$5:$B$135,PERSONAL!$H$5:$H$135),"-"))} -> Registrado solo en ENTREGADOS
A31: HISTORIAL DE MOVIMIENTOS DE LA CREDENCIAL (codigo en C5)
A32: ID_Movimiento | B32: Fecha | C32: Tipo_Movimiento | D32: Codigo_Activo | E32: Telefono | F32: Nombre | G32: Supervisor | H32: Regional | I32: Observaciones
A33: =IFERROR(_xlws.FILTER(TablaMovimientos,MOVIMIENTOS!$D$5:$D$53=$C$5),"Escriba un codigo BEX en C5 para ver su historial") -> Escriba un codigo BEX en C5 para ver su historial

Sheet INVENTARIO_GENERAL
A1: INVENTARIO GENERAL - Fuente central del sistema
A2: ? COMO USAR ESTA HOJA
A3: Cada credencial BEX aparece UNA sola vez. Las columnas en azul (Telefono, fechas, perdidas, dias) se calculan solas desde MOVIMIENTOS. Cambie Estado/Responsable y todo el sistema se actualiza.
A4: Codigo_Activo | B4: Tipo_Credencial | C4: Estado_Actual | D4: Responsable_Actual | E4: Telefono | F4: Supervisor | G4: Regional | H4: Fecha_Ultima_Asignacion | I4: Fecha_Ultima_Devolucion | J4: Cantidad_Perdidas | K4: Dias_En_Uso | L4: Observaciones
A5: BEX-0011 | B5: LEGACY (BEX-0xxx) | C5: ASIGNADO | D5: VLADIMIR SUTURI TOCOCARI | E5: {=IFERROR(XLOOKUP(#REF!,PERSONAL!$B$5:$B$135,PERSONAL!$A$5:$A$135),"POR REGISTRAR")} -> POR REGISTRAR | F5: PAMELA FANNY CALANI LAURA | G5: COCHABAMBA | H5: =IF(COUNTIFS(MOVIMIENTOS!$D$5:$D$53,#REF!)=0,"",MAXIFS(MOVIMIENTOS!$B$5:$B$53,MOVIMIENTOS!$D$5:$D$53,#REF!,MOVIMIENTOS!$C$5:$C$53,"<>DEVOLUCION")) | I5: =IF(COUNTIFS(MOVIMIENTOS!$D$5:$D$53,#REF!,MOVIMIENTOS!$C$5:$C$53,"DEVOLUCION")=0,"",MAXIFS(MOVIMIENTOS!$B$5:$B$53,MOVIMIENTOS!$D$5:$D$53,#REF!,MOVIMIENTOS!$C$5:$C$53,"DEVOLUCION")) | J5: =COUNTIFS(MOVIMIENTOS!$D$5:$D$53,#REF!,MOVIMIENTOS!$C$5:$C$53,"PERDIDA") -> 0 | K5: =IF(NOT(ISNUMBER(#REF!)),"",TODAY()-#REF!)
A6: BEX-0012 | B6: LEGACY (BEX-0xxx) | C6: ASIGNADO | D6: ROSIELVA ALDANA | E6: {=IFERROR(XLOOKUP(#REF!,PERSONAL!$B$5:$B$135,PERSONAL!$A$5:$A$135),"POR REGISTRAR")} -> POR REGISTRAR | F6: PAMELA FANNY CALANI LAURA | G6: COCHABAMBA | H6: =IF(COUNTIFS(MOVIMIENTOS!$D$5:$D$53,#REF!)=0,"",MAXIFS(MOVIMIENTOS!$B$5:$B$53,MOVIMIENTOS!$D$5:$D$53,#REF!,MOVIMIENTOS!$C$5:$C$53,"<>DEVOLUCION")) | I6: =IF(COUNTIFS(MOVIMIENTOS!$D$5:$D$53,#REF!,MOVIMIENTOS!$C$5:$C$53,"DEVOLUCION")=0,"",MAXIFS(MOVIMIENTOS!$B$5:$B$53,MOVIMIENTOS!$D$5:$D$53,#REF!,MOVIMIENTOS!$C$5:$C$53,"DEVOLUCION")) | J6: =COUNTIFS(MOVIMIENTOS!$D$5:$D$53,#REF!,MOVIMIENTOS!$C$5:$C$53,"PERDIDA") -> 0 | K6: =IF(NOT(ISNUMBER(#REF!)),"",TODAY()-#REF!)
A7: BEX-0013 | B7: LEGACY (BEX-0xxx) | C7: ASIGNADO | D7: VANIA GRAGEDA ESPINOZA | E7: {=IFERROR(XLOOKUP(#REF!,PERSONAL!$B$5:$B$135,PERSONAL!$A$5:$A$135),"POR REGISTRAR")} -> POR REGISTRAR | F7: PAMELA FANNY CALANI LAURA | G7: COCHABAMBA | H7: =IF(COUNTIFS(MOVIMIENTOS!$D$5:$D$53,#REF!)=0,"",MAXIFS(MOVIMIENTOS!$B$5:$B$53,MOVIMIENTOS!$D$5:$D$53,#REF!,MOVIMIENTOS!$C$5:$C$53,"<>DEVOLUCION")) | I7: =IF(COUNTIFS(MOVIMIENTOS!$D$5:$D$53,#REF!,MOVIMIENTOS!$C$5:$C$53,"DEVOLUCION")=0,"",MAXIFS(MOVIMIENTOS!$B$5:$B$53,MOVIMIENTOS!$D$5:$D$53,#REF!,MOVIMIENTOS!$C$5:$C$53,"DEVOLUCION")) | J7: =COUNTIFS(MOVIMIENTOS!$D$5:$D$53,#REF!,MOVIMIENTOS!$C$5:$C$53,"PERDIDA") -> 0 | K7: =IF(NOT(ISNUMBER(#REF!)),"",TODAY()-#REF!)
A8: BEX-0014 | B8: LEGACY (BEX-0xxx) | C8: ASIGNADO | D8: ALAN GUSTAVO ARNEZ TORO | E8: {=IFERROR(XLOOKUP(#REF!,PERSONAL!$B$5:$B$135,PERSONAL!$A$5:$A$135),"POR REGISTRAR")} -> POR REGISTRAR | F8: PAMELA FANNY CALANI LAURA | G8: COCHABAMBA | H8: =IF(COUNTIFS(MOVIMIENTOS!$D$5:$D$53,#REF!)=0,"",MAXIFS(MOVIMIENTOS!$B$5:$B$53,MOVIMIENTOS!$D$5:$D$53,#REF!,MOVIMIENTOS!$C$5:$C$53,"<>DEVOLUCION")) | I8: =IF(COUNTIFS(MOVIMIENTOS!$D$5:$D$53,#REF!,MOVIMIENTOS!$C$5:$C$53,"DEVOLUCION")=0,"",MAXIFS(MOVIMIENTOS!$B$5:$B$53,MOVIMIENTOS!$D$5:$D$53,#REF!,MOVIMIENTOS!$C$5:$C$53,"DEVOLUCION")) | J8: =COUNTIFS(MOVIMIENTOS!$D$5:$D$53,#REF!,MOVIMIENTOS!$C$5:$C$53,"PERDIDA") -> 0 | K8: =IF(NOT(ISNUMBER(#REF!)),"",TODAY()-#REF!)
A9: BEX-0015 | B9: LEGACY (BEX-0xxx) | C9: DISPONIBLE | D9: NO ASIGNADO | E9: {=IFERROR(XLOOKUP(#REF!,PERSONAL!$B$5:$B$135,PERSONAL!$A$5:$A$135),"POR REGISTRAR")} -> POR REGISTRAR | F9: PAMELA FANNY CALANI LAURA | G9: COCHABAMBA | H9: =IF(COUNTIFS(MOVIMIENTOS!$D$5:$D$53,#REF!)=0,"",MAXIFS(MOVIMIENTOS!$B$5:$B$53,MOVIMIENTOS!$D$5:$D$53,#REF!,MOVIMIENTOS!$C$5:$C$53,"<>DEVOLUCION")) | I9: =IF(COUNTIFS(MOVIMIENTOS!$D$5:$D$53,#REF!,MOVIMIENTOS!$C$5:$C$53,"DEVOLUCION")=0,"",MAXIFS(MOVIMIENTOS!$B$5:$B$53,MOVIMIENTOS!$D$5:$D$53,#REF!,MOVIMIENTOS!$C$5:$C$53,"DEVOLUCION")) | J9: =COUNTIFS(MOVIMIENTOS!$D$5:$D$53,#REF!,MOVIMIENTOS!$C$5:$C$53,"PERDIDA") -> 0 | K9: =IF(NOT(ISNUMBER(#REF!)),"",TODAY()-#REF!)
A10: BEX-0017 | B10: LEGACY (BEX-0xxx) | C10: ASIGNADO | D10: PAMELA FANNY CALANI LAURA | E10: {=IFERROR(XLOOKUP(#REF!,PERSONAL!$B$5:$B$135,PERSONAL!$A$5:$A$135),"POR REGISTRAR")} -> POR REGISTRAR | F10: PAMELA FANNY CALANI LAURA | G10: COCHABAMBA | H10: =IF(COUNTIFS(MOVIMIENTOS!$D$5:$D$53,#REF!)=0,"",MAXIFS(MOVIMIENTOS!$B$5:$B$53,MOVIMIENTOS!$D$5:$D$53,#REF!,MOVIMIENTOS!$C$5:$C$53,"<>DEVOLUCION")) | I10: =IF(COUNTIFS(MOVIMIENTOS!$D$5:$D$53,#REF!,MOVIMIENTOS!$C$5:$C$53,"DEVOLUCION")=0,"",MAXIFS(MOVIMIENTOS!$B$5:$B$53,MOVIMIENTOS!$D$5:$D$53,#REF!,MOVIMIENTOS!$C$5:$C$53,"DEVOLUCION")) | J10: =COUNTIFS(MOVIMIENTOS!$D$5:$D$53,#REF!,MOVIMIENTOS!$C$5:$C$53,"PERDIDA") -> 0 | K10: =IF(NOT(ISNUMBER(#REF!)),"",TODAY()-#REF!)
A11: BEX-0018 | B11: LEGACY (BEX-0xxx) | C11: ASIGNADO | D11: DIEGO ARMANDO COLQUE COLQUE | E11: {=IFERROR(XLOOKUP(#REF!,PERSONAL!$B$5:$B$135,PERSONAL!$A$5:$A$135),"POR REGISTRAR")} -> POR REGISTRAR | F11: PAMELA FANNY CALANI LAURA | G11: COCHABAMBA | H11: =IF(COUNTIFS(MOVIMIENTOS!$D$5:$D$53,#REF!)=0,"",MAXIFS(MOVIMIENTOS!$B$5:$B$53,MOVIMIENTOS!$D$5:$D$53,#REF!,MOVIMIENTOS!$C$5:$C$53,"<>DEVOLUCION")) | I11: =IF(COUNTIFS(MOVIMIENTOS!$D$5:$D$53,#REF!,MOVIMIENTOS!$C$5:$C$53,"DEVOLUCION")=0,"",MAXIFS(MOVIMIENTOS!$B$5:$B$53,MOVIMIENTOS!$D$5:$D$53,#REF!,MOVIMIENTOS!$C$5:$C$53,"DEVOLUCION")) | J11: =COUNTIFS(MOVIMIENTOS!$D$5:$D$53,#REF!,MOVIMIENTOS!$C$5:$C$53,"PERDIDA") -> 0 | K11: =IF(NOT(ISNUMBER(#REF!)),"",TODAY()-#REF!)
A12: BEX-0020 | B12: LEGACY (BEX-0xxx) | C12: ASIGNADO | D12: JHOJAN JAIRO CALLAHUARA CHOQUE | E12: {=IFERROR(XLOOKUP(#REF!,PERSONAL!$B$5:$B$135,PERSONAL!$A$5:$A$135),"POR REGISTRAR")} -> POR REGISTRAR | F12: PAMELA FANNY CALANI LAURA | G12: COCHABAMBA | H12: =IF(COUNTIFS(MOVIMIENTOS!$D$5:$D$53,#REF!)=0,"",MAXIFS(MOVIMIENTOS!$B$5:$B$53,MOVIMIENTOS!$D$5:$D$53,#REF!,MOVIMIENTOS!$C$5:$C$53,"<>DEVOLUCION")) | I12: =IF(COUNTIFS(MOVIMIENTOS!$D$5:$D$53,#REF!,MOVIMIENTOS!$C$5:$C$53,"DEVOLUCION")=0,"",MAXIFS(MOVIMIENTOS!$B$5:$B$53,MOVIMIENTOS!$D$5:$D$53,#REF!,MOVIMIENTOS!$C$5:$C$53,"DEVOLUCION")) | J12: =COUNTIFS(MOVIMIENTOS!$D$5:$D$53,#REF!,MOVIMIENTOS!$C$5:$C$53,"PERDIDA") -> 0 | K12: =IF(NOT(ISNUMBER(#REF!)),"",TODAY()-#REF!)
A13: BEX-0023 | B13: LEGACY (BEX-0xxx) | C13: ASIGNADO | D13: PABLO SANTIAGO PEREZ NAVA | E13: {=IFERROR(XLOOKUP(#REF!,PERSONAL!$B$5:$B$135,PERSONAL!$A$5:$A$135),"POR REGISTRAR")} -> POR REGISTRAR | F13: PAMELA FANNY CALANI LAURA | G13: COCHABAMBA | H13: =IF(COUNTIFS(MOVIMIENTOS!$D$5:$D$53,#REF!)=0,"",MAXIFS(MOVIMIENTOS!$B$5:$B$53,MOVIMIENTOS!$D$5:$D$53,#REF!,MOVIMIENTOS!$C$5:$C$53,"<>DEVOLUCION")) | I13: =IF(COUNTIFS(MOVIMIENTOS!$D$5:$D$53,#REF!,MOVIMIENTOS!$C$5:$C$53,"DEVOLUCION")=0,"",MAXIFS(MOVIMIENTOS!$B$5:$B$53,MOVIMIENTOS!$D$5:$D$53,#REF!,MOVIMIENTOS!$C$5:$C$53,"DEVOLUCION")) | J13: =COUNTIFS(MOVIMIENTOS!$D$5:$D$53,#REF!,MOVIMIENTOS!$C$5:$C$53,"PERDIDA") -> 0 | K13: =IF(NOT(ISNUMBER(#REF!)),"",TODAY()-#REF!)
A14: BEX-0027 | B14: LEGACY (BEX-0xxx) | C14: ASIGNADO | D14: JHENIFER LUCERO SERRUDO LLAMPA | E14: {=IFERROR(XLOOKUP(#REF!,PERSONAL!$B$5:$B$135,PERSONAL!$A$5:$A$135),"POR REGISTRAR")} -> POR REGISTRAR | F14: JENNY CRISTINA ECHALAR MONTALVO | G14: SUCRE | H14: =IF(COUNTIFS(MOVIMIENTOS!$D$5:$D$53,#REF!)=0,"",MAXIFS(MOVIMIENTOS!$B$5:$B$53,MOVIMIENTOS!$D$5:$D$53,#REF!,MOVIMIENTOS!$C$5:$C$53,"<>DEVOLUCION")) | I14: =IF(COUNTIFS(MOVIMIENTOS!$D$5:$D$53,#REF!,MOVIMIENTOS!$C$5:$C$53,"DEVOLUCION")=0,"",MAXIFS(MOVIMIENTOS!$B$5:$B$53,MOVIMIENTOS!$D$5:$D$53,#REF!,MOVIMIENTOS!$C$5:$C$53,"DEVOLUCION")) | J14: =COUNTIFS(MOVIMIENTOS!$D$5:$D$53,#REF!,MOVIMIENTOS!$C$5:$C$53,"PERDIDA") -> 0 | K14: =IF(NOT(ISNUMBER(#REF!)),"",TODAY()-#REF!)
A15: BEX-0033 | B15: LEGACY (BEX-0xxx) | C15: DISPONIBLE | D15: NO ASIGNADO | E15: {=IFERROR(XLOOKUP(#REF!,PERSONAL!$B$5:$B$135,PERSONAL!$A$5:$A$135),"POR REGISTRAR")} -> POR REGISTRAR | F15: PAMELA FANNY CALANI LAURA | G15: COCHABAMBA | H15: =IF(COUNTIFS(MOVIMIENTOS!$D$5:$D$53,#REF!)=0,"",MAXIFS(MOVIMIENTOS!$B$5:$B$53,MOVIMIENTOS!$D$5:$D$53,#REF!,MOVIMIENTOS!$C$5:$C$53,"<>DEVOLUCION")) | I15: =IF(COUNTIFS(MOVIMIENTOS!$D$5:$D$53,#REF!,MOVIMIENTOS!$C$5:$C$53,"DEVOLUCION")=0,"",MAXIFS(MOVIMIENTOS!$B$5:$B$53,MOVIMIENTOS!$D$5:$D$53,#REF!,MOVIMIENTOS!$C$5:$C$53,"DEVOLUCION")) | J15: =COUNTIFS(MOVIMIENTOS!$D$5:$D$53,#REF!,MOVIMIENTOS!$C$5:$C$53,"PERDIDA") -> 0 | K15: =IF(NOT(ISNUMBER(#REF!)),"",TODAY()-#REF!)
A16: BEX-0057 | B16: LEGACY (BEX-0xxx) | C16: ASIGNADO | D16: CALEB HERNAN FLORES FLORES | E16: {=IFERROR(XLOOKUP(#REF!,PERSONAL!$B$5:$B$135,PERSONAL!$A$5:$A$135),"POR REGISTRAR")} -> POR REGISTRAR | F16: PAMELA FANNY CALANI LAURA | G16: COCHABAMBA | H16: =IF(COUNTIFS(MOVIMIENTOS!$D$5:$D$53,#REF!)=0,"",MAXIFS(MOVIMIENTOS!$B$5:$B$53,MOVIMIENTOS!$D$5:$D$53,#REF!,MOVIMIENTOS!$C$5:$C$53,"<>DEVOLUCION")) | I16: =IF(COUNTIFS(MOVIMIENTOS!$D$5:$D$53,#REF!,MOVIMIENTOS!$C$5:$C$53,"DEVOLUCION")=0,"",MAXIFS(MOVIMIENTOS!$B$5:$B$53,MOVIMIENTOS!$D$5:$D$53,#REF!,MOVIMIENTOS!$C$5:$C$53,"DEVOLUCION")) | J16: =COUNTIFS(MOVIMIENTOS!$D$5:$D$53,#REF!,MOVIMIENTOS!$C$5:$C$53,"PERDIDA") -> 0 | K16: =IF(NOT(ISNUMBER(#REF!)),"",TODAY()-#REF!)
... A34: BEX-0150 | B34: LEGACY (BEX-0xxx) | C34: ASIGNADO | D34: RENE NUNEZ SOLIS | E34: {=IFERROR(XLOOKUP(#REF!,PERSONAL!$B$5:$B$135,PERSONAL!$A$5:$A$135),"POR REGISTRAR")} -> POR REGISTRAR | F34: JENNY CRISTINA ECHALAR MONTALVO | G34: SUCRE | H34: =IF(COUNTIFS(MOVIMIENTOS!$D$5:$D$53,#REF!)=0,"",MAXIFS(MOVIMIENTOS!$B$5:$B$53,MOVIMIENTOS!$D$5:$D$53,#REF!,MOVIMIENTOS!$C$5:$C$53,"<>DEVOLUCION")) | I34: =IF(COUNTIFS(MOVIMIENTOS!$D$5:$D$53,#REF!,MOVIMIENTOS!$C$5:$C$53,"DEVOLUCION")=0,"",MAXIFS(MOVIMIENTOS!$B$5:$B$53,MOVIMIENTOS!$D$5:$D$53,#REF!,MOVIMIENTOS!$C$5:$C$53,"DEVOLUCION")) | J34: =COUNTIFS(MOVIMIENTOS!$D$5:$D$53,#REF!,MOVIMIENTOS!$C$5:$C$53,"PERDIDA") -> 0 | K34: =IF(NOT(ISNUMBER(#REF!)),"",TODAY()-#REF!)
A35: BEX-0151 | B35: LEGACY (BEX-0xxx) | C35: DISPONIBLE | D35: SAMIEL ARTURO TORRICOS VILLARREAL | E35: {=IFERROR(XLOOKUP(#REF!,PERSONAL!$B$5:$B$135,PERSONAL!$A$5:$A$135),"POR REGISTRAR")} -> POR REGISTRAR | F35: CLAUDIA SHASKIA CALLE NINA | G35: LA PAZ | H35: =IF(COUNTIFS(MOVIMIENTOS!$D$5:$D$53,#REF!)=0,"",MAXIFS(MOVIMIENTOS!$B$5:$B$53,MOVIMIENTOS!$D$5:$D$53,#REF!,MOVIMIENTOS!$C$5:$C$53,"<>DEVOLUCION")) | I35: =IF(COUNTIFS(MOVIMIENTOS!$D$5:$D$53,#REF!,MOVIMIENTOS!$C$5:$C$53,"DEVOLUCION")=0,"",MAXIFS(MOVIMIENTOS!$B$5:$B$53,MOVIMIENTOS!$D$5:$D$53,#REF!,MOVIMIENTOS!$C$5:$C$53,"DEVOLUCION")) | J35: =COUNTIFS(MOVIMIENTOS!$D$5:$D$53,#REF!,MOVIMIENTOS!$C$5:$C$53,"PERDIDA") -> 0 | K35: =IF(NOT(ISNUMBER(#REF!)),"",TODAY()-#REF!) | L35: Credencial antiguo
A36: BEX-0152 | B36: LEGACY (BEX-0xxx) | C36: ASIGNADO | D36: BRUNO ROCHA PEREIRA | E36: {=IFERROR(XLOOKUP(#REF!,PERSONAL!$B$5:$B$135,PERSONAL!$A$5:$A$135),"POR REGISTRAR")} -> POR REGISTRAR | F36: HASIRA DANIELA OSINAGA CHOQUE | G36: COCHABAMBA | H36: =IF(COUNTIFS(MOVIMIENTOS!$D$5:$D$53,#REF!)=0,"",MAXIFS(MOVIMIENTOS!$B$5:$B$53,MOVIMIENTOS!$D$5:$D$53,#REF!,MOVIMIENTOS!$C$5:$C$53,"<>DEVOLUCION")) | I36: =IF(COUNTIFS(MOVIMIENTOS!$D$5:$D$53,#REF!,MOVIMIENTOS!$C$5:$C$53,"DEVOLUCION")=0,"",MAXIFS(MOVIMIENTOS!$B$5:$B$53,MOVIMIENTOS!$D$5:$D$53,#REF!,MOVIMIENTOS!$C$5:$C$53,"DEVOLUCION")) | J36: =COUNTIFS(MOVIMIENTOS!$D$5:$D$53,#REF!,MOVIMIENTOS!$C$5:$C$53,"PERDIDA") -> 0 | K36: =IF(NOT(ISNUMBER(#REF!)),"",TODAY()-#REF!)
A37: BEX-0155 | B37: LEGACY (BEX-0xxx) | C37: ASIGNADO | D37: CRISTIAN JAVIER MORALES REYES | E37: {=IFERROR(XLOOKUP(#REF!,PERSONAL!$B$5:$B$135,PERSONAL!$A$5:$A$135),"POR REGISTRAR")} -> POR REGISTRAR | F37: MILENKO ADRIANA ORDONEZ NUNEZ | G37: LA PAZ | H37: =IF(COUNTIFS(MOVIMIENTOS!$D$5:$D$53,#REF!)=0,"",MAXIFS(MOVIMIENTOS!$B$5:$B$53,MOVIMIENTOS!$D$5:$D$53,#REF!,MOVIMIENTOS!$C$5:$C$53,"<>DEVOLUCION")) | I37: =IF(COUNTIFS(MOVIMIENTOS!$D$5:$D$53,#REF!,MOVIMIENTOS!$C$5:$C$53,"DEVOLUCION")=0,"",MAXIFS(MOVIMIENTOS!$B$5:$B$53,MOVIMIENTOS!$D$5:$D$53,#REF!,MOVIMIENTOS!$C$5:$C$53,"DEVOLUCION")) | J37: =COUNTIFS(MOVIMIENTOS!$D$5:$D$53,#REF!,MOVIMIENTOS!$C$5:$C$53,"PERDIDA") -> 0 | K37: =IF(NOT(ISNUMBER(#REF!)),"",TODAY()-#REF!)
A38: BEX-0156 | B38: LEGACY (BEX-0xxx) | C38: ASIGNADO | D38: JORGE LUIS PEDRAZA | E38: {=IFERROR(XLOOKUP(#REF!,PERSONAL!$B$5:$B$135,PERSONAL!$A$5:$A$135),"POR REGISTRAR")} -> POR REGISTRAR | F38: MILENKO ADRIANA ORDONEZ NUNEZ | G38: LA PAZ | H38: =IF(COUNTIFS(MOVIMIENTOS!$D$5:$D$53,#REF!)=0,"",MAXIFS(MOVIMIENTOS!$B$5:$B$53,MOVIMIENTOS!$D$5:$D$53,#REF!,MOVIMIENTOS!$C$5:$C$53,"<>DEVOLUCION")) | I38: =IF(COUNTIFS(MOVIMIENTOS!$D$5:$D$53,#REF!,MOVIMIENTOS!$C$5:$C$53,"DEVOLUCION")=0,"",MAXIFS(MOVIMIENTOS!$B$5:$B$53,MOVIMIENTOS!$D$5:$D$53,#REF!,MOVIMIENTOS!$C$5:$C$53,"DEVOLUCION")) | J38: =COUNTIFS(MOVIMIENTOS!$D$5:$D$53,#REF!,MOVIMIENTOS!$C$5:$C$53,"PERDIDA") -> 0 | K38: =IF(NOT(ISNUMBER(#REF!)),"",TODAY()-#REF!)
A39: BEX-0158 | B39: LEGACY (BEX-0xxx) | C39: ASIGNADO | D39: JOEL DAVID HUANCA HUANCA | E39: {=IFERROR(XLOOKUP(#REF!,PERSONAL!$B$5:$B$135,PERSONAL!$A$5:$A$135),"POR REGISTRAR")} -> POR REGISTRAR | F39: JOEL DAVID HUANCA HUANCA | G39: LA PAZ | H39: =IF(COUNTIFS(MOVIMIENTOS!$D$5:$D$53,#REF!)=0,"",MAXIFS(MOVIMIENTOS!$B$5:$B$53,MOVIMIENTOS!$D$5:$D$53,#REF!,MOVIMIENTOS!$C$5:$C$53,"<>DEVOLUCION")) | I39: =IF(COUNTIFS(MOVIMIENTOS!$D$5:$D$53,#REF!,MOVIMIENTOS!$C$5:$C$53,"DEVOLUCION")=0,"",MAXIFS(MOVIMIENTOS!$B$5:$B$53,MOVIMIENTOS!$D$5:$D$53,#REF!,MOVIMIENTOS!$C$5:$C$53,"DEVOLUCION")) | J39: =COUNTIFS(MOVIMIENTOS!$D$5:$D$53,#REF!,MOVIMIENTOS!$C$5:$C$53,"PERDIDA") -> 0 | K39: =IF(NOT(ISNUMBER(#REF!)),"",TODAY()-#REF!)
A40: BEX-0162 | B40: LEGACY (BEX-0xxx) | C40: ASIGNADO | D40: AARON PEDRO CHUQUIMIA CHAIRA | E40: {=IFERROR(XLOOKUP(#REF!,PERSONAL!$B$5:$B$135,PERSONAL!$A$5:$A$135),"POR REGISTRAR")} -> POR REGISTRAR | F40: CLAUDIA SHASKIA CALLE NINA | G40: LA PAZ | H40: =IF(COUNTIFS(MOVIMIENTOS!$D$5:$D$53,#REF!)=0,"",MAXIFS(MOVIMIENTOS!$B$5:$B$53,MOVIMIENTOS!$D$5:$D$53,#REF!,MOVIMIENTOS!$C$5:$C$53,"<>DEVOLUCION")) | I40: =IF(COUNTIFS(MOVIMIENTOS!$D$5:$D$53,#REF!,MOVIMIENTOS!$C$5:$C$53,"DEVOLUCION")=0,"",MAXIFS(MOVIMIENTOS!$B$5:$B$53,MOVIMIENTOS!$D$5:$D$53,#REF!,MOVIMIENTOS!$C$5:$C$53,"DEVOLUCION")) | J40: =COUNTIFS(MOVIMIENTOS!$D$5:$D$53,#REF!,MOVIMIENTOS!$C$5:$C$53,"PERDIDA") -> 0 | K40: =IF(NOT(ISNUMBER(#REF!)),"",TODAY()-#REF!) | L40: Normalizado de BEX-162
A41: BEX-0166 | B41: LEGACY (BEX-0xxx) | C41: ASIGNADO | D41: KATTERIN VANESA MEDRANO ESPEJO | E41: {=IFERROR(XLOOKUP(#REF!,PERSONAL!$B$5:$B$135,PERSONAL!$A$5:$A$135),"POR REGISTRAR")} -> POR REGISTRAR | F41: MILENKO ADRIANA ORDONEZ NUNEZ | G41: LA PAZ | H41: =IF(COUNTIFS(MOVIMIENTOS!$D$5:$D$53,#REF!)=0,"",MAXIFS(MOVIMIENTOS!$B$5:$B$53,MOVIMIENTOS!$D$5:$D$53,#REF!,MOVIMIENTOS!$C$5:$C$53,"<>DEVOLUCION")) | I41: =IF(COUNTIFS(MOVIMIENTOS!$D$5:$D$53,#REF!,MOVIMIENTOS!$C$5:$C$53,"DEVOLUCION")=0,"",MAXIFS(MOVIMIENTOS!$B$5:$B$53,MOVIMIENTOS!$D$5:$D$53,#REF!,MOVIMIENTOS!$C$5:$C$53,"DEVOLUCION")) | J41: =COUNTIFS(MOVIMIENTOS!$D$5:$D$53,#REF!,MOVIMIENTOS!$C$5:$C$53,"PERDIDA") -> 0 | K41: =IF(NOT(ISNUMBER(#REF!)),"",TODAY()-#REF!)
A42: BEX-0167 | B42: LEGACY (BEX-0xxx) | C42: ASIGNADO | D42: ADRIANA ALEJANDRA AREVALO HERBAS | E42: {=IFERROR(XLOOKUP(#REF!,PERSONAL!$B$5:$B$135,PERSONAL!$A$5:$A$135),"POR REGISTRAR")} -> POR REGISTRAR | F42: MILENKO ADRIANA ORDONEZ NUNEZ | G42: LA PAZ | H42: =IF(COUNTIFS(MOVIMIENTOS!$D$5:$D$53,#REF!)=0,"",MAXIFS(MOVIMIENTOS!$B$5:$B$53,MOVIMIENTOS!$D$5:$D$53,#REF!,MOVIMIENTOS!$C$5:$C$53,"<>DEVOLUCION")) | I42: =IF(COUNTIFS(MOVIMIENTOS!$D$5:$D$53,#REF!,MOVIMIENTOS!$C$5:$C$53,"DEVOLUCION")=0,"",MAXIFS(MOVIMIENTOS!$B$5:$B$53,MOVIMIENTOS!$D$5:$D$53,#REF!,MOVIMIENTOS!$C$5:$C$53,"DEVOLUCION")) | J42: =COUNTIFS(MOVIMIENTOS!$D$5:$D$53,#REF!,MOVIMIENTOS!$C$5:$C$53,"PERDIDA") -> 0 | K42: =IF(NOT(ISNUMBER(#REF!)),"",TODAY()-#REF!)
A43: BEX-0169 | B43: LEGACY (BEX-0xxx) | C43: ASIGNADO | D43: MIGUEL ANGEL BLANCO RONDO | E43: {=IFERROR(XLOOKUP(#REF!,PERSONAL!$B$5:$B$135,PERSONAL!$A$5:$A$135),"POR REGISTRAR")} -> POR REGISTRAR | F43: CLAUDIA SHASKIA CALLE NINA | G43: LA PAZ | H43: =IF(COUNTIFS(MOVIMIENTOS!$D$5:$D$53,#REF!)=0,"",MAXIFS(MOVIMIENTOS!$B$5:$B$53,MOVIMIENTOS!$D$5:$D$53,#REF!,MOVIMIENTOS!$C$5:$C$53,"<>DEVOLUCION")) | I43: =IF(COUNTIFS(MOVIMIENTOS!$D$5:$D$53,#REF!,MOVIMIENTOS!$C$5:$C$53,"DEVOLUCION")=0,"",MAXIFS(MOVIMIENTOS!$B$5:$B$53,MOVIMIENTOS!$D$5:$D$53,#REF!,MOVIMIENTOS!$C$5:$C$53,"DEVOLUCION")) | J43: =COUNTIFS(MOVIMIENTOS!$D$5:$D$53,#REF!,MOVIMIENTOS!$C$5:$C$53,"PERDIDA") -> 0 | K43: =IF(NOT(ISNUMBER(#REF!)),"",TODAY()-#REF!)
A44: BEX-0176 | B44: LEGACY (BEX-0xxx) | C44: ASIGNADO | D44: CLAUDIA SHASKIA CALLE NINA / REYNA IVONNE CALLE NINA | E44: {=IFERROR(XLOOKUP(#REF!,PERSONAL!$B$5:$B$135,PERSONAL!$A$5:$A$135),"POR REGISTRAR")} -> POR REGISTRAR | F44: CLAUDIA SHASKIA CALLE NINA | G44: LA PAZ | H44: =IF(COUNTIFS(MOVIMIENTOS!$D$5:$D$53,#REF!)=0,"",MAXIFS(MOVIMIENTOS!$B$5:$B$53,MOVIMIENTOS!$D$5:$D$53,#REF!,MOVIMIENTOS!$C$5:$C$53,"<>DEVOLUCION")) | I44: =IF(COUNTIFS(MOVIMIENTOS!$D$5:$D$53,#REF!,MOVIMIENTOS!$C$5:$C$53,"DEVOLUCION")=0,"",MAXIFS(MOVIMIENTOS!$B$5:$B$53,MOVIMIENTOS!$D$5:$D$53,#REF!,MOVIMIENTOS!$C$5:$C$53,"DEVOLUCION")) | J44: =COUNTIFS(MOVIMIENTOS!$D$5:$D$53,#REF!,MOVIMIENTOS!$C$5:$C$53,"PERDIDA") -> 0 | K44: =IF(NOT(ISNUMBER(#REF!)),"",TODAY()-#REF!) | L44: ⚠️ DUPLICADO CRITICO: Mismo codigo asignado a 2 personas
A45: BEX-0179 | B45: LEGACY (BEX-0xxx) | C45: ASIGNADO | D45: MARIA EMILIA HUAYLLA ALMANZA | E45: {=IFERROR(XLOOKUP(#REF!,PERSONAL!$B$5:$B$135,PERSONAL!$A$5:$A$135),"POR REGISTRAR")} -> POR REGISTRAR | F45: MILENKO ADRIANA ORDONEZ NUNEZ | G45: LA PAZ | H45: =IF(COUNTIFS(MOVIMIENTOS!$D$5:$D$53,#REF!)=0,"",MAXIFS(MOVIMIENTOS!$B$5:$B$53,MOVIMIENTOS!$D$5:$D$53,#REF!,MOVIMIENTOS!$C$5:$C$53,"<>DEVOLUCION")) | I45: =IF(COUNTIFS(MOVIMIENTOS!$D$5:$D$53,#REF!,MOVIMIENTOS!$C$5:$C$53,"DEVOLUCION")=0,"",MAXIFS(MOVIMIENTOS!$B$5:$B$53,MOVIMIENTOS!$D$5:$D$53,#REF!,MOVIMIENTOS!$C$5:$C$53,"DEVOLUCION")) | J45: =COUNTIFS(MOVIMIENTOS!$D$5:$D$53,#REF!,MOVIMIENTOS!$C$5:$C$53,"PERDIDA") -> 0 | K45: =IF(NOT(ISNUMBER(#REF!)),"",TODAY()-#REF!)
A46: BEX-0184 | B46: LEGACY (BEX-0xxx) | C46: ASIGNADO | D46: DARING ACARAPI MAMANI | E46: {=IFERROR(XLOOKUP(#REF!,PERSONAL!$B$5:$B$135,PERSONAL!$A$5:$A$135),"POR REGISTRAR")} -> POR REGISTRAR | F46: GERCY EVER ERGUETA KIPPES | G46: LA PAZ | H46: =IF(COUNTIFS(MOVIMIENTOS!$D$5:$D$53,#REF!)=0,"",MAXIFS(MOVIMIENTOS!$B$5:$B$53,MOVIMIENTOS!$D$5:$D$53,#REF!,MOVIMIENTOS!$C$5:$C$53,"<>DEVOLUCION")) | I46: =IF(COUNTIFS(MOVIMIENTOS!$D$5:$D$53,#REF!,MOVIMIENTOS!$C$5:$C$53,"DEVOLUCION")=0,"",MAXIFS(MOVIMIENTOS!$B$5:$B$53,MOVIMIENTOS!$D$5:$D$53,#REF!,MOVIMIENTOS!$C$5:$C$53,"DEVOLUCION")) | J46: =COUNTIFS(MOVIMIENTOS!$D$5:$D$53,#REF!,MOVIMIENTOS!$C$5:$C$53,"PERDIDA") -> 0 | K46: =IF(NOT(ISNUMBER(#REF!)),"",TODAY()-#REF!) | L46: Normalizado de BEX-184
A47: BEX-0186 | B47: LEGACY (BEX-0xxx) | C47: ASIGNADO | D47: DANIELA ANDREA VARGAS AREVALO | E47: {=IFERROR(XLOOKUP(#REF!,PERSONAL!$B$5:$B$135,PERSONAL!$A$5:$A$135),"POR REGISTRAR")} -> POR REGISTRAR | F47: MILENKO ADRIANA ORDONEZ NUNEZ | G47: LA PAZ | H47: =IF(COUNTIFS(MOVIMIENTOS!$D$5:$D$53,#REF!)=0,"",MAXIFS(MOVIMIENTOS!$B$5:$B$53,MOVIMIENTOS!$D$5:$D$53,#REF!,MOVIMIENTOS!$C$5:$C$53,"<>DEVOLUCION")) | I47: =IF(COUNTIFS(MOVIMIENTOS!$D$5:$D$53,#REF!,MOVIMIENTOS!$C$5:$C$53,"DEVOLUCION")=0,"",MAXIFS(MOVIMIENTOS!$B$5:$B$53,MOVIMIENTOS!$D$5:$D$53,#REF!,MOVIMIENTOS!$C$5:$C$53,"DEVOLUCION")) | J47: =COUNTIFS(MOVIMIENTOS!$D$5:$D$53,#REF!,MOVIMIENTOS!$C$5:$C$53,"PERDIDA") -> 0 | K47: =IF(NOT(ISNUMBER(#REF!)),"",TODAY()-#REF!)
A48: BEX-0187 | B48: LEGACY (BEX-0xxx) | C48: ASIGNADO | D48: VANESSA ILLANES YUJRA | E48: {=IFERROR(XLOOKUP(#REF!,PERSONAL!$B$5:$B$135,PERSONAL!$A$5:$A$135),"POR REGISTRAR")} -> POR REGISTRAR | F48: JOEL DAVID HUANCA HUANCA | G48: LA PAZ | H48: =IF(COUNTIFS(MOVIMIENTOS!$D$5:$D$53,#REF!)=0,"",MAXIFS(MOVIMIENTOS!$B$5:$B$53,MOVIMIENTOS!$D$5:$D$53,#REF!,MOVIMIENTOS!$C$5:$C$53,"<>DEVOLUCION")) | I48: =IF(COUNTIFS(MOVIMIENTOS!$D$5:$D$53,#REF!,MOVIMIENTOS!$C$5:$C$53,"DEVOLUCION")=0,"",MAXIFS(MOVIMIENTOS!$B$5:$B$53,MOVIMIENTOS!$D$5:$D$53,#REF!,MOVIMIENTOS!$C$5:$C$53,"DEVOLUCION")) | J48: =COUNTIFS(MOVIMIENTOS!$D$5:$D$53,#REF!,MOVIMIENTOS!$C$5:$C$53,"PERDIDA") -> 0 | K48: =IF(NOT(ISNUMBER(#REF!)),"",TODAY()-#REF!)
A49: BEX-0192 | B49: LEGACY (BEX-0xxx) | C49: ASIGNADO | D49: FRANZ RODRIGO LEVANDRO PANUNI | E49: {=IFERROR(XLOOKUP(#REF!,PERSONAL!$B$5:$B$135,PERSONAL!$A$5:$A$135),"POR REGISTRAR")} -> POR REGISTRAR | F49: JOEL DAVID HUANCA HUANCA | G49: LA PAZ | H49: =IF(COUNTIFS(MOVIMIENTOS!$D$5:$D$53,#REF!)=0,"",MAXIFS(MOVIMIENTOS!$B$5:$B$53,MOVIMIENTOS!$D$5:$D$53,#REF!,MOVIMIENTOS!$C$5:$C$53,"<>DEVOLUCION")) | I49: =IF(COUNTIFS(MOVIMIENTOS!$D$5:$D$53,#REF!,MOVIMIENTOS!$C$5:$C$53,"DEVOLUCION")=0,"",MAXIFS(MOVIMIENTOS!$B$5:$B$53,MOVIMIENTOS!$D$5:$D$53,#REF!,MOVIMIENTOS!$C$5:$C$53,"DEVOLUCION")) | J49: =COUNTIFS(MOVIMIENTOS!$D$5:$D$53,#REF!,MOVIMIENTOS!$C$5:$C$53,"PERDIDA") -> 0 | K49: =IF(NOT(ISNUMBER(#REF!)),"",TODAY()-#REF!)
A50: BEX-0195 | B50: LEGACY (BEX-0xxx) | C50: DISPONIBLE | D50: LORENA (INACTIVO) | E50: {=IFERROR(XLOOKUP(#REF!,PERSONAL!$B$5:$B$135,PERSONAL!$A$5:$A$135),"POR REGISTRAR")} -> POR REGISTRAR | F50: BEATRIZ OVIEDO OVIEDO | G50: SANTA CRUZ | H50: =IF(COUNTIFS(MOVIMIENTOS!$D$5:$D$53,#REF!)=0,"",MAXIFS(MOVIMIENTOS!$B$5:$B$53,MOVIMIENTOS!$D$5:$D$53,#REF!,MOVIMIENTOS!$C$5:$C$53,"<>DEVOLUCION")) | I50: =IF(COUNTIFS(MOVIMIENTOS!$D$5:$D$53,#REF!,MOVIMIENTOS!$C$5:$C$53,"DEVOLUCION")=0,"",MAXIFS(MOVIMIENTOS!$B$5:$B$53,MOVIMIENTOS!$D$5:$D$53,#REF!,MOVIMIENTOS!$C$5:$C$53,"DEVOLUCION")) | J50: =COUNTIFS(MOVIMIENTOS!$D$5:$D$53,#REF!,MOVIMIENTOS!$C$5:$C$53,"PERDIDA") -> 0 | K50: =IF(NOT(ISNUMBER(#REF!)),"",TODAY()-#REF!) | L50: Persona inactiva - nombre incompleto
A51: BEX-0196 | B51: LEGACY (BEX-0xxx) | C51: ASIGNADO | D51: BEATRIZ OVIEDO OVIEDO | E51: {=IFERROR(XLOOKUP(#REF!,PERSONAL!$B$5:$B$135,PERSONAL!$A$5:$A$135),"POR REGISTRAR")} -> POR REGISTRAR | F51: BEATRIZ OVIEDO OVIEDO | G51: SANTA CRUZ | H51: =IF(COUNTIFS(MOVIMIENTOS!$D$5:$D$53,#REF!)=0,"",MAXIFS(MOVIMIENTOS!$B$5:$B$53,MOVIMIENTOS!$D$5:$D$53,#REF!,MOVIMIENTOS!$C$5:$C$53,"<>DEVOLUCION")) | I51: =IF(COUNTIFS(MOVIMIENTOS!$D$5:$D$53,#REF!,MOVIMIENTOS!$C$5:$C$53,"DEVOLUCION")=0,"",MAXIFS(MOVIMIENTOS!$B$5:$B$53,MOVIMIENTOS!$D$5:$D$53,#REF!,MOVIMIENTOS!$C$5:$C$53,"DEVOLUCION")) | J51: =COUNTIFS(MOVIMIENTOS!$D$5:$D$53,#REF!,MOVIMIENTOS!$C$5:$C$53,"PERDIDA") -> 0 | K51: =IF(NOT(ISNUMBER(#REF!)),"",TODAY()-#REF!)
A52: BEX-0198 | B52: LEGACY (BEX-0xxx) | C52: ASIGNADO | D52: JENNY CRISTINA ECHALAR MONTALVO | E52: {=IFERROR(XLOOKUP(#REF!,PERSONAL!$B$5:$B$135,PERSONAL!$A$5:$A$135),"POR REGISTRAR")} -> POR REGISTRAR | F52: JENNY CRISTINA ECHALAR MONTALVO | G52: SUCRE | H52: =IF(COUNTIFS(MOVIMIENTOS!$D$5:$D$53,#REF!)=0,"",MAXIFS(MOVIMIENTOS!$B$5:$B$53,MOVIMIENTOS!$D$5:$D$53,#REF!,MOVIMIENTOS!$C$5:$C$53,"<>DEVOLUCION")) | I52: =IF(COUNTIFS(MOVIMIENTOS!$D$5:$D$53,#REF!,MOVIMIENTOS!$C$5:$C$53,"DEVOLUCION")=0,"",MAXIFS(MOVIMIENTOS!$B$5:$B$53,MOVIMIENTOS!$D$5:$D$53,#REF!,MOVIMIENTOS!$C$5:$C$53,"DEVOLUCION")) | J52: =COUNTIFS(MOVIMIENTOS!$D$5:$D$53,#REF!,MOVIMIENTOS!$C$5:$C$53,"PERDIDA") -> 0 | K52: =IF(NOT(ISNUMBER(#REF!)),"",TODAY()-#REF!) | L52: Normalizado de BEX-198
A53: BEX-0298 | B53: LEGACY (BEX-0xxx) | C53: ASIGNADO | D53: HASIRA DANIELA OSINAGA CHOQUE | E53: {=IFERROR(XLOOKUP(#REF!,PERSONAL!$B$5:$B$135,PERSONAL!$A$5:$A$135),"POR REGISTRAR")} -> POR REGISTRAR | F53: HASIRA DANIELA OSINAGA CHOQUE | G53: COCHABAMBA | H53: =IF(COUNTIFS(MOVIMIENTOS!$D$5:$D$53,#REF!)=0,"",MAXIFS(MOVIMIENTOS!$B$5:$B$53,MOVIMIENTOS!$D$5:$D$53,#REF!,MOVIMIENTOS!$C$5:$C$53,"<>DEVOLUCION")) | I53: =IF(COUNTIFS(MOVIMIENTOS!$D$5:$D$53,#REF!,MOVIMIENTOS!$C$5:$C$53,"DEVOLUCION")=0,"",MAXIFS(MOVIMIENTOS!$B$5:$B$53,MOVIMIENTOS!$D$5:$D$53,#REF!,MOVIMIENTOS!$C$5:$C$53,"DEVOLUCION")) | J53: =COUNTIFS(MOVIMIENTOS!$D$5:$D$53,#REF!,MOVIMIENTOS!$C$5:$C$53,"PERDIDA") -> 0 | K53: =IF(NOT(ISNUMBER(#REF!)),"",TODAY()-#REF!)
A54: BEX-0368 | B54: LEGACY (BEX-0xxx) | C54: ASIGNADO | D54: DANIELA LUCERO FLAVIA MIRANDA | E54: {=IFERROR(XLOOKUP(#REF!,PERSONAL!$B$5:$B$135,PERSONAL!$A$5:$A$135),"POR REGISTRAR")} -> POR REGISTRAR | F54: CLAUDIA SHASKIA CALLE NINA | G54: LA PAZ | H54: =IF(COUNTIFS(MOVIMIENTOS!$D$5:$D$53,#REF!)=0,"",MAXIFS(MOVIMIENTOS!$B$5:$B$53,MOVIMIENTOS!$D$5:$D$53,#REF!,MOVIMIENTOS!$C$5:$C$53,"<>DEVOLUCION")) | I54: =IF(COUNTIFS(MOVIMIENTOS!$D$5:$D$53,#REF!,MOVIMIENTOS!$C$5:$C$53,"DEVOLUCION")=0,"",MAXIFS(MOVIMIENTOS!$B$5:$B$53,MOVIMIENTOS!$D$5:$D$53,#REF!,MOVIMIENTOS!$C$5:$C$53,"DEVOLUCION")) | J54: =COUNTIFS(MOVIMIENTOS!$D$5:$D$53,#REF!,MOVIMIENTOS!$C$5:$C$53,"PERDIDA") -> 0 | K54: =IF(NOT(ISNUMBER(#REF!)),"",TODAY()-#REF!)
A55: BEX-0501 | B55: LEGACY (BEX-0xxx) | C55: ASIGNADO | D55: LUIS FERNANDO ARAGUIRA CHAMO | E55: {=IFERROR(XLOOKUP(#REF!,PERSONAL!$B$5:$B$135,PERSONAL!$A$5:$A$135),"POR REGISTRAR")} -> POR REGISTRAR | F55: BEATRIZ OVIEDO OVIEDO | G55: SANTA CRUZ | H55: =IF(COUNTIFS(MOVIMIENTOS!$D$5:$D$53,#REF!)=0,"",MAXIFS(MOVIMIENTOS!$B$5:$B$53,MOVIMIENTOS!$D$5:$D$53,#REF!,MOVIMIENTOS!$C$5:$C$53,"<>DEVOLUCION")) | I55: =IF(COUNTIFS(MOVIMIENTOS!$D$5:$D$53,#REF!,MOVIMIENTOS!$C$5:$C$53,"DEVOLUCION")=0,"",MAXIFS(MOVIMIENTOS!$B$5:$B$53,MOVIMIENTOS!$D$5:$D$53,#REF!,MOVIMIENTOS!$C$5:$C$53,"DEVOLUCION")) | J55: =COUNTIFS(MOVIMIENTOS!$D$5:$D$53,#REF!,MOVIMIENTOS!$C$5:$C$53,"PERDIDA") -> 0 | K55: =IF(NOT(ISNUMBER(#REF!)),"",TODAY()-#REF!)
A56: BEX-0505 | B56: LEGACY (BEX-0xxx) | C56: ASIGNADO | D56: TOMAS (NOMBRE INCOMPLETO) | E56: {=IFERROR(XLOOKUP(#REF!,PERSONAL!$B$5:$B$135,PERSONAL!$A$5:$A$135),"POR REGISTRAR")} -> POR REGISTRAR | F56: BEATRIZ OVIEDO OVIEDO | G56: SANTA CRUZ | H56: =IF(COUNTIFS(MOVIMIENTOS!$D$5:$D$53,#REF!)=0,"",MAXIFS(MOVIMIENTOS!$B$5:$B$53,MOVIMIENTOS!$D$5:$D$53,#REF!,MOVIMIENTOS!$C$5:$C$53,"<>DEVOLUCION")) | I56: =IF(COUNTIFS(MOVIMIENTOS!$D$5:$D$53,#REF!,MOVIMIENTOS!$C$5:$C$53,"DEVOLUCION")=0,"",MAXIFS(MOVIMIENTOS!$B$5:$B$53,MOVIMIENTOS!$D$5:$D$53,#REF!,MOVIMIENTOS!$C$5:$C$53,"DEVOLUCION")) | J56: =COUNTIFS(MOVIMIENTOS!$D$5:$D$53,#REF!,MOVIMIENTOS!$C$5:$C$53,"PERDIDA") -> 0 | K56: =IF(NOT(ISNUMBER(#REF!)),"",TODAY()-#REF!) | L56: Completar nombre
A57: BEX-0510 | B57: LEGACY (BEX-0xxx) | C57: ASIGNADO | D57: JIMENA RIVERO LOAYZA | E57: {=IFERROR(XLOOKUP(#REF!,PERSONAL!$B$5:$B$135,PERSONAL!$A$5:$A$135),"POR REGISTRAR")} -> POR REGISTRAR | F57: BEATRIZ OVIEDO OVIEDO | G57: SANTA CRUZ | H57: =IF(COUNTIFS(MOVIMIENTOS!$D$5:$D$53,#REF!)=0,"",MAXIFS(MOVIMIENTOS!$B$5:$B$53,MOVIMIENTOS!$D$5:$D$53,#REF!,MOVIMIENTOS!$C$5:$C$53,"<>DEVOLUCION")) | I57: =IF(COUNTIFS(MOVIMIENTOS!$D$5:$D$53,#REF!,MOVIMIENTOS!$C$5:$C$53,"DEVOLUCION")=0,"",MAXIFS(MOVIMIENTOS!$B$5:$B$53,MOVIMIENTOS!$D$5:$D$53,#REF!,MOVIMIENTOS!$C$5:$C$53,"DEVOLUCION")) | J57: =COUNTIFS(MOVIMIENTOS!$D$5:$D$53,#REF!,MOVIMIENTOS!$C$5:$C$53,"PERDIDA") -> 0 | K57: =IF(NOT(ISNUMBER(#REF!)),"",TODAY()-#REF!)
...

Sheet PERSONAL
A1: TABLA MAESTRA DE PERSONAL
A2: ? COMO USAR ESTA HOJA
A3: Registro unico de personas. El identificador principal es el Telefono. El sistema relaciona a cada persona con su credencial y movimientos por el nombre/telefono.
A4: Telefono | B4: Nombre_Completo | C4: Rol | D4: Supervisor | E4: Regional | F4: Estado | G4: Credencial_Actual | H4: Observaciones
A5: POR REGISTRAR | B5: HASIRA DANIELA OSINAGA CHOQUE | C5: SUPERVISOR | D5: HASIRA DANIELA OSINAGA CHOQUE | E5: COCHABAMBA | F5: ACTIVO | G5: BEX-0298
A6: POR REGISTRAR | B6: BRUNO ROCHA PEREIRA | C6: AFILIADOR | D6: HASIRA DANIELA OSINAGA CHOQUE | E6: COCHABAMBA | F6: ACTIVO | G6: BEX-0152
A7: POR REGISTRAR | B7: JOSE OLAF ROJAS CONDARCO | C7: AFILIADOR | D7: HASIRA DANIELA OSINAGA CHOQUE | E7: COCHABAMBA | F7: ACTIVO | G7: BEX-0532
A8: POR REGISTRAR | B8: EVELYN CARMELA ESPINOZA CASTRO | C8: AFILIADOR | D8: HASIRA DANIELA OSINAGA CHOQUE | E8: COCHABAMBA | F8: ACTIVO | G8: BEX-0511
A9: POR REGISTRAR | B9: HEYDY DAYANA PUTARE MACHACA | C9: AFILIADOR | D9: HASIRA DANIELA OSINAGA CHOQUE | E9: COCHABAMBA | F9: ACTIVO | G9: BEX-0528
A10: POR REGISTRAR | B10: JOHANNA CASSANDRA CHAVEZ VALERIANO | C10: AFILIADOR | D10: HASIRA DANIELA OSINAGA CHOQUE | E10: COCHABAMBA | F10: ACTIVO | G10: BEX-0522
A11: POR REGISTRAR | B11: LAURA ANDREA TRIBENO GUTIERREZ | C11: AFILIADOR | D11: HASIRA DANIELA OSINAGA CHOQUE | E11: COCHABAMBA | F11: ACTIVO | G11: BEX-0533
A12: POR REGISTRAR | B12: MARCELO RIVAS MARIN | C12: AFILIADOR | D12: HASIRA DANIELA OSINAGA CHOQUE | E12: COCHABAMBA | F12: ACTIVO | G12: BEX-0525
A13: POR REGISTRAR | B13: SARAI VANESA TERAN GONZALES | C13: AFILIADOR | D13: HASIRA DANIELA OSINAGA CHOQUE | E13: COCHABAMBA | F13: ACTIVO | G13: BEX-0517
A14: POR REGISTRAR | B14: PAMELA FANNY CALANI LAURA | C14: SUPERVISOR | D14: PAMELA FANNY CALANI LAURA | E14: COCHABAMBA | F14: ACTIVO | G14: BEX-0017
A15: POR REGISTRAR | B15: ALAN GUSTAVO ARNEZ TORO | C15: AFILIADOR | D15: PAMELA FANNY CALANI LAURA | E15: COCHABAMBA | F15: ACTIVO | G15: BEX-0014
A16: POR REGISTRAR | B16: CALEB HERNAN FLORES FLORES | C16: AFILIADOR | D16: PAMELA FANNY CALANI LAURA | E16: COCHABAMBA | F16: ACTIVO | G16: BEX-0057
... A18: POR REGISTRAR | B18: PABLO SANTIAGO PEREZ NAVA | C18: AFILIADOR | D18: PAMELA FANNY CALANI LAURA | E18: COCHABAMBA | F18: ACTIVO | G18: BEX-0023
A19: POR REGISTRAR | B19: ROSIELVA ALDANA | C19: AFILIADOR | D19: PAMELA FANNY CALANI LAURA | E19: COCHABAMBA | F19: ACTIVO | G19: BEX-0012 | H19: Nombre incompleto - verificar
A20: POR REGISTRAR | B20: VANIA GRAGEDA ESPINOZA | C20: AFILIADOR | D20: PAMELA FANNY CALANI LAURA | E20: COCHABAMBA | F20: ACTIVO | G20: BEX-0013
A21: POR REGISTRAR | B21: VLADIMIR SUTURI TOCOCARI | C21: AFILIADOR | D21: PAMELA FANNY CALANI LAURA | E21: COCHABAMBA | F21: ACTIVO | G21: BEX-0011
A22: POR REGISTRAR | B22: JHOJAN JAIRO CALLAHUARA CHOQUE | C22: AFILIADOR | D22: PAMELA FANNY CALANI LAURA | E22: COCHABAMBA | F22: ACTIVO | G22: BEX-0020
A23: POR REGISTRAR | B23: NATALIA VILLARROEL | C23: SUPERVISOR | D23: NATALIA VILLARROEL | E23: COCHABAMBA | F23: ACTIVO | H23: Supervisor registrado en ENTREGADOS - datos incompletos
A24: POR REGISTRAR | B24: CLAUDIA SHASKIA CALLE NINA | C24: SUPERVISOR | D24: CLAUDIA SHASKIA CALLE NINA | E24: LA PAZ | F24: ACTIVO | G24: BEX-0176 | H24: ⚠️ BEX-0176 DUPLICADO - verificar con REYNA IVONNE
A25: POR REGISTRAR | B25: AARON PEDRO CHUQUIMIA CHAIRA | C25: AFILIADOR | D25: CLAUDIA SHASKIA CALLE NINA | E25: LA PAZ | F25: ACTIVO | G25: BEX-0162
A26: POR REGISTRAR | B26: EIMI SONIA CHUQUIMIA CHAIRA | C26: AFILIADOR | D26: CLAUDIA SHASKIA CALLE NINA | E26: LA PAZ | F26: ACTIVO | G26: BEX-0112
A27: POR REGISTRAR | B27: LUZ NATALIA HUANAPACO PENA | C27: AFILIADOR | D27: CLAUDIA SHASKIA CALLE NINA | E27: LA PAZ | F27: INACTIVO
A28: POR REGISTRAR | B28: MIGUEL ANGEL BLANCO RONDO | C28: AFILIADOR | D28: CLAUDIA SHASKIA CALLE NINA | E28: LA PAZ | F28: ACTIVO | G28: BEX-0169
A29: POR REGISTRAR | B29: REYNA IVONNE CALLE NINA | C29: AFILIADOR | D29: CLAUDIA SHASKIA CALLE NINA | E29: LA PAZ | F29: ACTIVO | G29: BEX-0176 | H29: ⚠️ BEX-0176 DUPLICADO - misma credencial que CLAUDIA SHASKIA
A30: POR REGISTRAR | B30: RUBEN ANTONIO HINOJOSA TUPA | C30: AFILIADOR | D30: CLAUDIA SHASKIA CALLE NINA | E30: LA PAZ | F30: ACTIVO | G30: BEX-0120
A31: POR REGISTRAR | B31: SAMIEL ARTURO TORRICOS VILLARREAL | C31: AFILIADOR | D31: CLAUDIA SHASKIA CALLE NINA | E31: LA PAZ | F31: INACTIVO | G31: BEX-0151
A32: POR REGISTRAR | B32: DANIELA LUCERO FLAVIA MIRANDA | C32: AFILIADOR | D32: CLAUDIA SHASKIA CALLE NINA | E32: LA PAZ | F32: ACTIVO | G32: BEX-0368
A33: POR REGISTRAR | B33: GERCY EVER ERGUETA KIPPES | C33: SUPERVISOR | D33: GERCY EVER ERGUETA KIPPES | E33: LA PAZ | F33: ACTIVO | G33: BEX-2038 | H33: Nueva credencial asignada
A34: POR REGISTRAR | B34: ABIGAIL HUANACO TICONA | C34: AFILIADOR | D34: GERCY EVER ERGUETA KIPPES | E34: LA PAZ | F34: INACTIVO
A35: POR REGISTRAR | B35: ALEXIA MICAELA ERGUETA ALIAGA | C35: AFILIADOR | D35: GERCY EVER ERGUETA KIPPES | E35: LA PAZ | F35: ACTIVO | G35: BEX-2037
A36: POR REGISTRAR | B36: ALVARO CIMAR MAMANI PRADO | C36: AFILIADOR | D36: GERCY EVER ERGUETA KIPPES | E36: LA PAZ | F36: INACTIVO
A37: POR REGISTRAR | B37: ANA GABRIELA CONDORI HERRERA | C37: AFILIADOR | D37: GERCY EVER ERGUETA KIPPES | E37: LA PAZ | F37: INACTIVO
A38: POR REGISTRAR | B38: BENJAMIN CHUQUIMIA CORDERO | C38: AFILIADOR | D38: GERCY EVER ERGUETA KIPPES | E38: LA PAZ | F38: INACTIVO
A39: POR REGISTRAR | B39: DARING ACARAPI MAMANI | C39: AFILIADOR | D39: GERCY EVER ERGUETA KIPPES | E39: LA PAZ | F39: ACTIVO | G39: BEX-0184
A40: POR REGISTRAR | B40: GIOVANA TOLA CASACA | C40: AFILIADOR | D40: GERCY EVER ERGUETA KIPPES | E40: LA PAZ | F40: INACTIVO
A41: POR REGISTRAR | B41: HARRY JHONNY CRUZ MALLQUI | C41: AFILIADOR | D41: GERCY EVER ERGUETA KIPPES | E41: LA PAZ | F41: INACTIVO
...

Sheet MOVIMIENTOS
A1: HISTORIAL DE MOVIMIENTOS - Registro permanente
A2: ? COMO USAR ESTA HOJA
A3: Agregue una fila por cada evento (asignacion, devolucion, perdida, etc.). NUNCA borre filas. Al agregar un movimiento, el inventario, el buscador y el dashboard se actualizan automaticamente.
A4: ID_Movimiento | B4: Fecha | C4: Tipo_Movimiento | D4: Codigo_Activo | E4: Telefono | F4: Nombre | G4: Supervisor | H4: Regional | I4: Observaciones
A5: MOV-0001 | B5: 46169 | C5: ENTREGA INICIAL | D5: BEX-2000 | E5: POR REGISTRAR | F5: JORGE SAAVEDRA | G5: JORGE SAAVEDRA | H5: SANTA CRUZ | I5: Lote inaugural entregado a supervisor
A6: MOV-0002 | B6: 46169 | C6: ENTREGA INICIAL | D6: BEX-2001 | E6: POR REGISTRAR | F6: POR ASIGNAR | G6: DELIA JORDAN FACUSSE | H6: SANTA CRUZ
A7: MOV-0003 | B7: 46169 | C7: ENTREGA INICIAL | D7: BEX-2002 | E7: POR REGISTRAR | F7: POR ASIGNAR | G7: DELIA JORDAN FACUSSE | H7: SANTA CRUZ
A8: MOV-0004 | B8: 46169 | C8: ENTREGA INICIAL | D8: BEX-2003 | E8: POR REGISTRAR | F8: POR ASIGNAR | G8: DELIA JORDAN FACUSSE | H8: SANTA CRUZ
A9: MOV-0005 | B9: 46169 | C9: ENTREGA INICIAL | D9: BEX-2004 | E9: POR REGISTRAR | F9: POR ASIGNAR | G9: DELIA JORDAN FACUSSE | H9: SANTA CRUZ
A10: MOV-0006 | B10: 46169 | C10: ENTREGA INICIAL | D10: BEX-2005 | E10: POR REGISTRAR | F10: POR ASIGNAR | G10: DELIA JORDAN FACUSSE | H10: SANTA CRUZ
A11: MOV-0007 | B11: 46174 | C11: ENTREGA INICIAL | D11: BEX-2006 | E11: POR REGISTRAR | F11: POR ASIGNAR | G11: JOSE GUTIERREZ PEDRAZA | H11: SANTA CRUZ
A12: MOV-0008 | B12: 46174 | C12: ENTREGA INICIAL | D12: BEX-2007 | E12: POR REGISTRAR | F12: POR ASIGNAR | G12: JOSE GUTIERREZ PEDRAZA | H12: SANTA CRUZ
A13: MOV-0009 | B13: 46174 | C13: ENTREGA INICIAL | D13: BEX-2008 | E13: POR REGISTRAR | F13: POR ASIGNAR | G13: JOSE GUTIERREZ PEDRAZA | H13: SANTA CRUZ
A14: MOV-0010 | B14: 46174 | C14: ENTREGA INICIAL | D14: BEX-2009 | E14: POR REGISTRAR | F14: POR ASIGNAR | G14: JOSE GUTIERREZ PEDRAZA | H14: SANTA CRUZ
A15: MOV-0011 | B15: 46175 | C15: ENTREGA INICIAL | D15: BEX-2010 | E15: POR REGISTRAR | F15: POR ASIGNAR | G15: MARIA FERNANDA DAZA PALMA | H15: TARIJA
A16: MOV-0012 | B16: 46175 | C16: ENTREGA INICIAL | D16: BEX-2011 | E16: POR REGISTRAR | F16: POR ASIGNAR | G16: MARIA FERNANDA DAZA PALMA | H16: TARIJA
A17: MOV-0013 | B17: 46175 | C17: ENTREGA INICIAL | D17: BEX-2012 | E17: POR REGISTRAR | F17: POR ASIGNAR | G17: MARIA FERNANDA DAZA PALMA | H17: TARIJA
... A49: MOV-0045 | B49: 46176 | C49: ENTREGA INICIAL | D49: BEX-2044 | E49: POR REGISTRAR | F49: ARACELI MARLENE TAPIA GUERRA | G49: MIRIAM ROSA CHAMBI QUISPE | H49: ORURO
A50: MOV-0046 | B50: 46176 | C50: REPOSICION | D50: BEX-2045 | E50: POR REGISTRAR | F50: BRENDA XIMENA BARBA VACA | G50: BEATRIZ OVIEDO OVIEDO | H50: SANTA CRUZ | I50: Reposicion por perdida
A51: MOV-0047 | B51: 46176 | C51: REPOSICION | D51: BEX-2046 | E51: POR REGISTRAR | F51: MARCO ANTONIO ESCOBAR ALVAREZ | G51: BEATRIZ OVIEDO OVIEDO | H51: SANTA CRUZ | I51: Reposicion - perdio BEX-0518
A52: MOV-0048 | B52: 46176 | C52: PERDIDA | D52: BEX-0518 | E52: POR REGISTRAR | F52: MARCO ANTONIO ESCOBAR ALVAREZ | G52: BEATRIZ OVIEDO OVIEDO | H52: SANTA CRUZ | I52: COBRAR POR PERDIDA
A53: MOV-0049 | B53: 46176 | C53: PERDIDA | D53: BEX-2045 | E53: POR REGISTRAR | F53: BRENDA XIMENA BARBA VACA | G53: BEATRIZ OVIEDO OVIEDO | H53: SANTA CRUZ | I53: Credencial anterior perdida - COBRAR

Sheet PARAMETROS
A1: PARAMETROS DEL SISTEMA - BEX
A2: ? COMO USAR ESTA HOJA
A3: Listas maestras que alimentan los menus desplegables y validaciones del sistema. Edite aqui para agregar regionales, supervisores o estados. Las demas hojas se actualizan solas.
A4: Regionales | B4: Estados_Persona | C4: Roles | D4: Estados_Credencial | E4: Tipos_Movimiento | F4: Generacion | G4: Supervisores | I4: ERRORES / ALERTAS DETECTADAS
A5: COCHABAMBA | B5: ACTIVO | C5: AFILIADOR | D5: ASIGNADO | E5: ASIGNACION | F5: NUEVA (BEX-2xxx) | G5: HASIRA DANIELA OSINAGA CHOQUE | I5: 1. BEX-0176 asignado a DOS personas: CLAUDIA SHASKIA y REYNA IVONNE
A6: LA PAZ | B6: INACTIVO | C6: SUPERVISOR | D6: DISPONIBLE | E6: ENTREGA INICIAL | F6: LEGACY (BEX-0xxx) | G6: PAMELA FANNY CALANI LAURA | I6: 2. BEX-0106 posiblemente duplicado: CAMILA LOZA (GERCY) y JHOSEP SHARUM (MAGALI)
A7: ORURO | D7: POR ASIGNAR | E7: DEVOLUCION | G7: NATALIA VILLARROEL | I7: 3. Personas con nombres incompletos: TOMAS, LORENA, SELMA
A8: SANTA CRUZ | D8: PERDIDO | E8: PERDIDA | G8: CLAUDIA SHASKIA CALLE NINA | I8: 4. BEX-0518 reportada como PERDIDA - pendiente cobro a MARCO ESCOBAR
A9: SUCRE | E9: REPOSICION | G9: GERCY EVER ERGUETA KIPPES | I9: 5. Supervisores sin datos en hoja principal: LIONEL CHABUR, NATALIA VILLARROEL
A10: TARIJA | E10: REASIGNACION | G10: JOEL DAVID HUANCA HUANCA | I10: 6. Codigos normalizados (espacios y ceros): BEX-162, BEX-0176, BEX-027, etc.
E11: CAMBIO SUPERVISOR | G11: MAGALI YESENIA HUANCA HUANCA | I11: 7. Telefonos marcados como POR REGISTRAR - campo critico faltante
E12: CAMBIO REGIONAL | G12: MILENKO ADRIANA ORDONEZ NUNEZ
E13: BAJA | G13: LIONEL CHABUR
G14: MIRIAM ROSA CHAMBI QUISPE
G15: JORGE SAAVEDRA
G16: BEATRIZ OVIEDO OVIEDO
G17: DELIA JORDAN FACUSSE
G18: JOSE GUTIERREZ PEDRAZA
G19: JENNY CRISTINA ECHALAR MONTALVO
G20: MARIA FERNANDA DAZA PALMA

Sheet MOTOR_DASHBOARD
A1: MOTOR DE CALCULO (hoja oculta) - alimenta KPIs, tablas resumen y graficos
A3: Estado | B3: Cantidad | D3: Regional | E3: Cantidad | G3: Supervisor | H3: Asignadas | J3: Mes | K3: Movimientos | L3: Entregas | M3: Perdidas | O3: ini | P3: fin | U3: fReg | V3: fSup | W3: fEst | X3: fMes
A4: ASIGNADO | B4: =COUNTIF(INVENTARIO_GENERAL!$C$5:$C$181,A4) -> 73 | D4: COCHABAMBA | E4: =COUNTIF(INVENTARIO_GENERAL!$G$5:$G$181,D4) -> 30 | G4: MILENKO ADRIANA ORDONEZ NUNEZ | H4: =COUNTIFS(INVENTARIO_GENERAL!$F$5:$F$181,G4,INVENTARIO_GENERAL!$C$5:$C$181,"ASIGNADO") -> 10 | J4: 2026-05 | K4: =COUNTIFS(MOVIMIENTOS!$B$5:$B$53,">="&O4,MOVIMIENTOS!$B$5:$B$53,"<="&P4) -> 6 | L4: =COUNTIFS(MOVIMIENTOS!$B$5:$B$53,">="&O4,MOVIMIENTOS!$B$5:$B$53,"<="&P4,MOVIMIENTOS!$C$5:$C$53,"ENTREGA INICIAL")+COUNTIFS(MOVIMIENTOS!$B$5:$B$53,">="&O4,MOVIMIENTOS!$B$5:$B$53,"<="&P4,MOVIMIENTOS!$C$5:$C$53,"ASIGNACION") -> 6 | M4: =COUNTIFS(MOVIMIENTOS!$B$5:$B$53,">="&O4,MOVIMIENTOS!$B$5:$B$53,"<="&P4,MOVIMIENTOS!$C$5:$C$53,"PERDIDA") -> 0 | O4: 46143 | P4: 46173 | U4: (TODOS) | V4: (TODOS) | W4: (TODOS) | X4: (TODOS)
A5: DISPONIBLE | B5: =COUNTIF(INVENTARIO_GENERAL!$C$5:$C$181,A5) -> 68 | D5: LA PAZ | E5: =COUNTIF(INVENTARIO_GENERAL!$G$5:$G$181,D5) -> 39 | G5: MIRIAM ROSA CHAMBI QUISPE | H5: =COUNTIFS(INVENTARIO_GENERAL!$F$5:$F$181,G5,INVENTARIO_GENERAL!$C$5:$C$181,"ASIGNADO") -> 10 | J5: 2026-06 | K5: =COUNTIFS(MOVIMIENTOS!$B$5:$B$53,">="&O5,MOVIMIENTOS!$B$5:$B$53,"<="&P5) -> 43 | L5: =COUNTIFS(MOVIMIENTOS!$B$5:$B$53,">="&O5,MOVIMIENTOS!$B$5:$B$53,"<="&P5,MOVIMIENTOS!$C$5:$C$53,"ENTREGA INICIAL")+COUNTIFS(MOVIMIENTOS!$B$5:$B$53,">="&O5,MOVIMIENTOS!$B$5:$B$53,"<="&P5,MOVIMIENTOS!$C$5:$C$53,"ASIGNACION") -> 39 | M5: =COUNTIFS(MOVIMIENTOS!$B$5:$B$53,">="&O5,MOVIMIENTOS!$B$5:$B$53,"<="&P5,MOVIMIENTOS!$C$5:$C$53,"PERDIDA") -> 2 | O5: 46174 | P5: 46203 | U5: COCHABAMBA | V5: HASIRA DANIELA OSINAGA CHOQUE | W5: ASIGNADO | X5: 2026-05
A6: POR ASIGNAR | B6: =COUNTIF(INVENTARIO_GENERAL!$C$5:$C$181,A6) -> 35 | D6: ORURO | E6: =COUNTIF(INVENTARIO_GENERAL!$G$5:$G$181,D6) -> 10 | G6: HASIRA DANIELA OSINAGA CHOQUE | H6: =COUNTIFS(INVENTARIO_GENERAL!$F$5:$F$181,G6,INVENTARIO_GENERAL!$C$5:$C$181,"ASIGNADO") -> 9 | J6: 2026-07 | K6: =COUNTIFS(MOVIMIENTOS!$B$5:$B$53,">="&O6,MOVIMIENTOS!$B$5:$B$53,"<="&P6) -> 0 | L6: =COUNTIFS(MOVIMIENTOS!$B$5:$B$53,">="&O6,MOVIMIENTOS!$B$5:$B$53,"<="&P6,MOVIMIENTOS!$C$5:$C$53,"ENTREGA INICIAL")+COUNTIFS(MOVIMIENTOS!$B$5:$B$53,">="&O6,MOVIMIENTOS!$B$5:$B$53,"<="&P6,MOVIMIENTOS!$C$5:$C$53,"ASIGNACION") -> 0 | M6: =COUNTIFS(MOVIMIENTOS!$B$5:$B$53,">="&O6,MOVIMIENTOS!$B$5:$B$53,"<="&P6,MOVIMIENTOS!$C$5:$C$53,"PERDIDA") -> 0 | O6: 46204 | P6: 46234 | U6: LA PAZ | V6: PAMELA FANNY CALANI LAURA | W6: DISPONIBLE | X6: 2026-06
A7: PERDIDO | B7: =COUNTIF(INVENTARIO_GENERAL!$C$5:$C$181,A7) -> 1 | D7: SANTA CRUZ | E7: =COUNTIF(INVENTARIO_GENERAL!$G$5:$G$181,D7) -> 85 | G7: PAMELA FANNY CALANI LAURA | H7: =COUNTIFS(INVENTARIO_GENERAL!$F$5:$F$181,G7,INVENTARIO_GENERAL!$C$5:$C$181,"ASIGNADO") -> 9 | J7: 2026-08 | K7: =COUNTIFS(MOVIMIENTOS!$B$5:$B$53,">="&O7,MOVIMIENTOS!$B$5:$B$53,"<="&P7) -> 0 | L7: =COUNTIFS(MOVIMIENTOS!$B$5:$B$53,">="&O7,MOVIMIENTOS!$B$5:$B$53,"<="&P7,MOVIMIENTOS!$C$5:$C$53,"ENTREGA INICIAL")+COUNTIFS(MOVIMIENTOS!$B$5:$B$53,">="&O7,MOVIMIENTOS!$B$5:$B$53,"<="&P7,MOVIMIENTOS!$C$5:$C$53,"ASIGNACION") -> 0 | M7: =COUNTIFS(MOVIMIENTOS!$B$5:$B$53,">="&O7,MOVIMIENTOS!$B$5:$B$53,"<="&P7,MOVIMIENTOS!$C$5:$C$53,"PERDIDA") -> 0 | O7: 46235 | P7: 46265 | U7: ORURO | V7: NATALIA VILLARROEL | W7: POR ASIGNAR | X7: 2026-07
D8: SUCRE | E8: =COUNTIF(INVENTARIO_GENERAL!$G$5:$G$181,D8) -> 6 | G8: CLAUDIA SHASKIA CALLE NINA | H8: =COUNTIFS(INVENTARIO_GENERAL!$F$5:$F$181,G8,INVENTARIO_GENERAL!$C$5:$C$181,"ASIGNADO") -> 6 | J8: 2026-09 | K8: =COUNTIFS(MOVIMIENTOS!$B$5:$B$53,">="&O8,MOVIMIENTOS!$B$5:$B$53,"<="&P8) -> 0 | L8: =COUNTIFS(MOVIMIENTOS!$B$5:$B$53,">="&O8,MOVIMIENTOS!$B$5:$B$53,"<="&P8,MOVIMIENTOS!$C$5:$C$53,"ENTREGA INICIAL")+COUNTIFS(MOVIMIENTOS!$B$5:$B$53,">="&O8,MOVIMIENTOS!$B$5:$B$53,"<="&P8,MOVIMIENTOS!$C$5:$C$53,"ASIGNACION") -> 0 | M8: =COUNTIFS(MOVIMIENTOS!$B$5:$B$53,">="&O8,MOVIMIENTOS!$B$5:$B$53,"<="&P8,MOVIMIENTOS!$C$5:$C$53,"PERDIDA") -> 0 | O8: 46266 | P8: 46295 | U8: SANTA CRUZ | V8: CLAUDIA SHASKIA CALLE NINA | W8: PERDIDO | X8: 2026-08
D9: TARIJA | E9: =COUNTIF(INVENTARIO_GENERAL!$G$5:$G$181,D9) -> 7 | G9: JOEL DAVID HUANCA HUANCA | H9: =COUNTIFS(INVENTARIO_GENERAL!$F$5:$F$181,G9,INVENTARIO_GENERAL!$C$5:$C$181,"ASIGNADO") -> 7 | J9: 2026-10 | K9: =COUNTIFS(MOVIMIENTOS!$B$5:$B$53,">="&O9,MOVIMIENTOS!$B$5:$B$53,"<="&P9) -> 0 | L9: =COUNTIFS(MOVIMIENTOS!$B$5:$B$53,">="&O9,MOVIMIENTOS!$B$5:$B$53,"<="&P9,MOVIMIENTOS!$C$5:$C$53,"ENTREGA INICIAL")+COUNTIFS(MOVIMIENTOS!$B$5:$B$53,">="&O9,MOVIMIENTOS!$B$5:$B$53,"<="&P9,MOVIMIENTOS!$C$5:$C$53,"ASIGNACION") -> 0 | M9: =COUNTIFS(MOVIMIENTOS!$B$5:$B$53,">="&O9,MOVIMIENTOS!$B$5:$B$53,"<="&P9,MOVIMIENTOS!$C$5:$C$53,"PERDIDA") -> 0 | O9: 46296 | P9: 46326 | U9: SUCRE | V9: GERCY EVER ERGUETA KIPPES | X9: 2026-09
G10: BEATRIZ OVIEDO OVIEDO | H10: =COUNTIFS(INVENTARIO_GENERAL!$F$5:$F$181,G10,INVENTARIO_GENERAL!$C$5:$C$181,"ASIGNADO") -> 6 | J10: 2026-11 | K10: =COUNTIFS(MOVIMIENTOS!$B$5:$B$53,">="&O10,MOVIMIENTOS!$B$5:$B$53,"<="&P10) -> 0 | L10: =COUNTIFS(MOVIMIENTOS!$B$5:$B$53,">="&O10,MOVIMIENTOS!$B$5:$B$53,"<="&P10,MOVIMIENTOS!$C$5:$C$53,"ENTREGA INICIAL")+COUNTIFS(MOVIMIENTOS!$B$5:$B$53,">="&O10,MOVIMIENTOS!$B$5:$B$53,"<="&P10,MOVIMIENTOS!$C$5:$C$53,"ASIGNACION") -> 0 | M10: =COUNTIFS(MOVIMIENTOS!$B$5:$B$53,">="&O10,MOVIMIENTOS!$B$5:$B$53,"<="&P10,MOVIMIENTOS!$C$5:$C$53,"PERDIDA") -> 0 | O10: 46327 | P10: 46356 | U10: TARIJA | V10: JOEL DAVID HUANCA HUANCA | X10: 2026-10
G11: JENNY CRISTINA ECHALAR MONTALVO | H11: =COUNTIFS(INVENTARIO_GENERAL!$F$5:$F$181,G11,INVENTARIO_GENERAL!$C$5:$C$181,"ASIGNADO") -> 6 | J11: 2026-12 | K11: =COUNTIFS(MOVIMIENTOS!$B$5:$B$53,">="&O11,MOVIMIENTOS!$B$5:$B$53,"<="&P11) -> 0 | L11: =COUNTIFS(MOVIMIENTOS!$B$5:$B$53,">="&O11,MOVIMIENTOS!$B$5:$B$53,"<="&P11,MOVIMIENTOS!$C$5:$C$53,"ENTREGA INICIAL")+COUNTIFS(MOVIMIENTOS!$B$5:$B$53,">="&O11,MOVIMIENTOS!$B$5:$B$53,"<="&P11,MOVIMIENTOS!$C$5:$C$53,"ASIGNACION") -> 0 | M11: =COUNTIFS(MOVIMIENTOS!$B$5:$B$53,">="&O11,MOVIMIENTOS!$B$5:$B$53,"<="&P11,MOVIMIENTOS!$C$5:$C$53,"PERDIDA") -> 0 | O11: 46357 | P11: 46387 | V11: MAGALI YESENIA HUANCA HUANCA | X11: 2026-11
